Workbook

Sheet 2965D
C2: 661 VGS | D2: A/C Number | F2: ZE633 | H2: A/C Tail Letters | L2: =IF($F2="", "",VLOOKUP(F2,Aircraft[#all],2,FALSE())) -> XX | N2: Date | O2: 46067
B4: F724 Hours B/F | C4: 119.90764
B5: F724 Launches B/F | C5: 22503 | E5: Launches Left (If 32 or less) | R5: F724 Entry Guide at the bottom of sheet
A7: Ser No. | G7: Trainee | J7: SCT | L7: Claimed By | N7: Other (G) | O7: SPC | P7: SPC (Hours/Minutes) | S7: PLF | T7: After Flight Initials
G8: GIF | H8: G/S | I8: AGT | J8: QGI | K8: U/T
B9: Aircraft Commander | C9: 2nd Pilot/Trainee or Passenger | D9: Duty | E9: Take Off Time | F9: Landing Time | G9: (B) | H9: (C) | I9: (D) | J9: (E) | K9: (F) | L9: P1 | M9: P2 | P9: 1 | Q9: 6 | R9: 7 | U9: Warnings | V9: Soaring | W9: Aeros
A10: 1 | B10: Jennings | C10: Smith | D10: GIF | E10: 0.45833333 | F10: 0.46388889 | G10: =IF($D10="","",IF($D10=G$8,$F10-$E10,"")) -> 0.0055555556 | H10: =IF($D10="","",IF($D10=H$8,$F10-$E10,"")) | I10: =IF($D10="","",IF($D10=I$8,$F10-$E10,"")) | J10: =IF($D10="","",IF($D10=CONCATENATE(J$7," ",J$8),$F10-$E10,"")) | K10: =IF($D10="","",IF($D10=CONCATENATE(J$7," ",K$8),$F10-$E10,"")) | N10: =IF($D10="","",IF($D10="PAX",$F10-$E10,"")) | O10: =IF(ISBLANK(F10),"",IF(W10=TRUE(),7,IF(V10=TRUE(),6,1))) -> 6 | P10: =IF($O10=P$9,F10-E10,"") | Q10: =IF($O10=6,F10-E10,"") -> 0.0055555556 | R10: =IF($O10=R$9,F10-E10,"") | U10: =IF($G$5=A10,"Max Launches","") | V10: TRUE | W10: =FALSE() -> FALSE
A11: 2 | B11: Jennings | C11: Smith | D11: GIF | E11: 0.46944444 | F11: 0.47291667 | G11: =IF($D11="","",IF($D11=G$8,$F11-$E11,"")) -> 0.0034722222 | H11: =IF($D11="","",IF($D11=H$8,$F11-$E11,"")) | I11: =IF($D11="","",IF($D11=I$8,$F11-$E11,"")) | J11: =IF($D11="","",IF($D11=CONCATENATE(J$7," ",J$8),$F11-$E11,"")) | K11: =IF($D11="","",IF($D11=CONCATENATE(J$7," ",K$8),$F11-$E11,"")) | N11: =IF($D11="","",IF($D11="PAX",$F11-$E11,"")) | O11: =IF(ISBLANK(F11), "", IF(W11=TRUE(),7,IF(V11=TRUE(),6,1))) -> 1 | P11: =IF($O11=P$9,F11-E11,"") -> 0.0034722222 | Q11: =IF($O11=6,F11-E11,"") | R11: =IF($O11=R$9,F11-E11,"") | U11: =IF($G$5=A11,"Max Launches","") | V11: =FALSE() -> FALSE | W11: =FALSE() -> FALSE
A12: 3 | B12: Jennings | C12: Derp | D12: GIF | E12: 0.47777778 | F12: 0.48125 | G12: =IF($D12="","",IF($D12=G$8,$F12-$E12,"")) -> 0.0034722222 | H12: =IF($D12="","",IF($D12=H$8,$F12-$E12,"")) | I12: =IF($D12="","",IF($D12=I$8,$F12-$E12,"")) | J12: =IF($D12="","",IF($D12=CONCATENATE(J$7," ",J$8),$F12-$E12,"")) | K12: =IF($D12="","",IF($D12=CONCATENATE(J$7," ",K$8),$F12-$E12,"")) | N12: =IF($D12="","",IF($D12="PAX",$F12-$E12,"")) | O12: =IF(ISBLANK(F12), "", IF(W12=TRUE(),7,IF(V12=TRUE(),6,1))) -> 1 | P12: =IF($O12=P$9,F12-E12,"") -> 0.0034722222 | Q12: =IF($O12=6,F12-E12,"") | R12: =IF($O12=R$9,F12-E12,"") | U12: =IF($G$5=A12,"Max Launches","") | V12: =FALSE() -> FALSE | W12: =FALSE() -> FALSE
A13: 4 | B13: Jennings | C13: Derp | D13: GIF | E13: 0.48611111 | F13: 0.48888889 | G13: =IF($D13="","",IF($D13=G$8,$F13-$E13,"")) -> 0.0027777778 | H13: =IF($D13="","",IF($D13=H$8,$F13-$E13,"")) | I13: =IF($D13="","",IF($D13=I$8,$F13-$E13,"")) | J13: =IF($D13="","",IF($D13=CONCATENATE(J$7," ",J$8),$F13-$E13,"")) | K13: =IF($D13="","",IF($D13=CONCATENATE(J$7," ",K$8),$F13-$E13,"")) | N13: =IF($D13="","",IF($D13="PAX",$F13-$E13,"")) | O13: =IF(ISBLANK(F13), "", IF(W13=TRUE(),7,IF(V13=TRUE(),6,1))) -> 1 | P13: =IF($O13=P$9,F13-E13,"") -> 0.0027777778 | Q13: =IF($O13=6,F13-E13,"") | R13: =IF($O13=R$9,F13-E13,"") | U13: =IF($G$5=A13,"Max Launches","") | V13: =FALSE() -> FALSE | W13: =FALSE() -> FALSE
A14: 5 | B14: Jennings | C14: Bojangles | D14: GIF | E14: 0.49444444 | F14: 0.49861111 | G14: =IF($D14="","",IF($D14=G$8,$F14-$E14,"")) -> 0.0041666667 | H14: =IF($D14="","",IF($D14=H$8,$F14-$E14,"")) | I14: =IF($D14="","",IF($D14=I$8,$F14-$E14,"")) | J14: =IF($D14="","",IF($D14=CONCATENATE(J$7," ",J$8),$F14-$E14,"")) | K14: =IF($D14="","",IF($D14=CONCATENATE(J$7," ",K$8),$F14-$E14,"")) | N14: =IF($D14="","",IF($D14="PAX",$F14-$E14,"")) | O14: =IF(ISBLANK(F14), "", IF(W14=TRUE(),7,IF(V14=TRUE(),6,1))) -> 7 | P14: =IF($O14=P$9,F14-E14,"") | Q14: =IF($O14=6,F14-E14,"") | R14: =IF($O14=R$9,F14-E14,"") -> 0.0041666667 | U14: =IF($G$5=A14,"Max Launches","") | V14: =FALSE() -> FALSE | W14: TRUE
A15: 6 | B15: Jennings | C15: Bojangles | D15: GIF | E15: 0.50347222 | F15: 0.50625 | G15: =IF($D15="","",IF($D15=G$8,$F15-$E15,"")) -> 0.0027777778 | H15: =IF($D15="","",IF($D15=H$8,$F15-$E15,"")) | I15: =IF($D15="","",IF($D15=I$8,$F15-$E15,"")) | J15: =IF($D15="","",IF($D15=CONCATENATE(J$7," ",J$8),$F15-$E15,"")) | K15: =IF($D15="","",IF($D15=CONCATENATE(J$7," ",K$8),$F15-$E15,"")) | N15: =IF($D15="","",IF($D15="PAX",$F15-$E15,"")) | O15: =IF(ISBLANK(F15), "", IF(W15=TRUE(),7,IF(V15=TRUE(),6,1))) -> 1 | P15: =IF($O15=P$9,F15-E15,"") -> 0.0027777778 | Q15: =IF($O15=6,F15-E15,"") | R15: =IF($O15=R$9,F15-E15,"") | U15: =IF($G$5=A15,"Max Launches","") | V15: =FALSE() -> FALSE | W15: =FALSE() -> FALSE
A16: 7 | B16: Jennings | C16: Bloggs | D16: AGT | E16: 0.62638889 | F16: 0.62916667 | G16: =IF($D16="","",IF($D16=G$8,$F16-$E16,"")) | H16: =IF($D16="","",IF($D16=H$8,$F16-$E16,"")) | I16: =IF($D16="","",IF($D16=I$8,$F16-$E16,"")) -> 0.0027777778 | J16: =IF($D16="","",IF($D16=CONCATENATE(J$7," ",J$8),$F16-$E16,"")) | K16: =IF($D16="","",IF($D16=CONCATENATE(J$7," ",K$8),$F16-$E16,"")) | N16: =IF($D16="","",IF($D16="PAX",$F16-$E16,"")) | O16: =IF(ISBLANK(F16), "", IF(W16=TRUE(),7,IF(V16=TRUE(),6,1))) -> 1 | P16: =IF($O16=P$9,F16-E16,"") -> 0.0027777778 | Q16: =IF($O16=6,F16-E16,"") | R16: =IF($O16=R$9,F16-E16,"") | U16: =IF($G$5=A16,"Max Launches","") | V16: =FALSE() -> FALSE | W16: =FALSE() -> FALSE
A17: 8 | B17: Jennings | C17: Bloggs | D17: AGT | E17: 0.63611111 | F17: 0.63958333 | G17: =IF($D17="","",IF($D17=G$8,$F17-$E17,"")) | H17: =IF($D17="","",IF($D17=H$8,$F17-$E17,"")) | I17: =IF($D17="","",IF($D17=I$8,$F17-$E17,"")) -> 0.0034722222 | J17: =IF($D17="","",IF($D17=CONCATENATE(J$7," ",J$8),$F17-$E17,"")) | K17: =IF($D17="","",IF($D17=CONCATENATE(J$7," ",K$8),$F17-$E17,"")) | N17: =IF($D17="","",IF($D17="PAX",$F17-$E17,"")) | O17: =IF(ISBLANK(F17), "", IF(W17=TRUE(),7,IF(V17=TRUE(),6,1))) -> 1 | P17: =IF($O17=P$9,F17-E17,"") -> 0.0034722222 | Q17: =IF($O17=6,F17-E17,"") | R17: =IF($O17=R$9,F17-E17,"") | U17: =IF($G$5=A17,"Max Launches","") | V17: =FALSE() -> FALSE | W17: =FALSE() -> FALSE
A18: 9 | B18: Jennings | C18: Bloggs | D18: AGT | E18: 0.64513889 | F18: 0.64861111 | G18: =IF($D18="","",IF($D18=G$8,$F18-$E18,"")) | H18: =IF($D18="","",IF($D18=H$8,$F18-$E18,"")) | I18: =IF($D18="","",IF($D18=I$8,$F18-$E18,"")) -> 0.0034722222 | J18: =IF($D18="","",IF($D18=CONCATENATE(J$7," ",J$8),$F18-$E18,"")) | K18: =IF($D18="","",IF($D18=CONCATENATE(J$7," ",K$8),$F18-$E18,"")) | N18: =IF($D18="","",IF($D18="PAX",$F18-$E18,"")) | O18: =IF(ISBLANK(F18), "", IF(W18=TRUE(),7,IF(V18=TRUE(),6,1))) -> 1 | P18: =IF($O18=P$9,F18-E18,"") -> 0.0034722222 | Q18: =IF($O18=6,F18-E18,"") | R18: =IF($O18=R$9,F18-E18,"") | U18: =IF($G$5=A18,"Max Launches","") | V18: =FALSE() -> FALSE | W18: =FALSE() -> FALSE
A19: 10 | B19: Jennings | C19: Bloggs | D19: AGT | E19: 0.65625 | F19: 0.65972222 | G19: =IF($D19="","",IF($D19=G$8,$F19-$E19,"")) | H19: =IF($D19="","",IF($D19=H$8,$F19-$E19,"")) | I19: =IF($D19="","",IF($D19=I$8,$F19-$E19,"")) -> 0.0034722222 | J19: =IF($D19="","",IF($D19=CONCATENATE(J$7," ",J$8),$F19-$E19,"")) | K19: =IF($D19="","",IF($D19=CONCATENATE(J$7," ",K$8),$F19-$E19,"")) | N19: =IF($D19="","",IF($D19="PAX",$F19-$E19,"")) | O19: =IF(ISBLANK(F19), "", IF(W19=TRUE(),7,IF(V19=TRUE(),6,1))) -> 1 | P19: =IF($O19=P$9,F19-E19,"") -> 0.0034722222 | Q19: =IF($O19=6,F19-E19,"") | R19: =IF($O19=R$9,F19-E19,"") | U19: =IF($G$5=A19,"Max Launches","") | V19: =FALSE() -> FALSE | W19: =FALSE() -> FALSE
A20: 11 | B20: Abbott | C20: Bloggs | D20: SCT QGI | E20: 0.66875 | F20: 0.67222222 | G20: =IF($D20="","",IF($D20=G$8,$F20-$E20,"")) | H20: =IF($D20="","",IF($D20=H$8,$F20-$E20,"")) | I20: =IF($D20="","",IF($D20=I$8,$F20-$E20,"")) | J20: =IF($D20="","",IF($D20=CONCATENATE(J$7," ",J$8),$F20-$E20,"")) -> 0.0034722222 | K20: =IF($D20="","",IF($D20=CONCATENATE(J$7," ",K$8),$F20-$E20,"")) | N20: =IF($D20="","",IF($D20="PAX",$F20-$E20,"")) | O20: =IF(ISBLANK(F20), "", IF(W20=TRUE(),7,IF(V20=TRUE(),6,1))) -> 1 | P20: =IF($O20=P$9,F20-E20,"") -> 0.0034722222 | Q20: =IF($O20=6,F20-E20,"") | R20: =IF($O20=R$9,F20-E20,"") | U20: =IF($G$5=A20,"Max Launches","") | V20: =FALSE() -> FALSE | W20: =FALSE() -> FALSE
A21: 12 | B21: Abbott | C21: Bloggs | D21: SCT U/T | E21: 0.68055556 | F21: 0.68402778 | G21: =IF($D21="","",IF($D21=G$8,$F21-$E21,"")) | H21: =IF($D21="","",IF($D21=H$8,$F21-$E21,"")) | I21: =IF($D21="","",IF($D21=I$8,$F21-$E21,"")) | J21: =IF($D21="","",IF($D21=CONCATENATE(J$7," ",J$8),$F21-$E21,"")) | K21: =IF($D21="","",IF($D21=CONCATENATE(J$7," ",K$8),$F21-$E21,"")) -> 0.0034722222 | N21: =IF($D21="","",IF($D21="PAX",$F21-$E21,"")) | O21: =IF(ISBLANK(F21), "", IF(W21=TRUE(),7,IF(V21=TRUE(),6,1))) -> 1 | P21: =IF($O21=P$9,F21-E21,"") -> 0.0034722222 | Q21: =IF($O21=6,F21-E21,"") | R21: =IF($O21=R$9,F21-E21,"") | U21: =IF($G$5=A21,"Max Launches","") | V21: =FALSE() -> FALSE | W21: =FALSE() -> FALSE
A22: 13 | B22: Abbott | C22: Bloggs | D22: PAX | E22: 0.69027778 | F22: 0.69305556 | G22: =IF($D22="","",IF($D22=G$8,$F22-$E22,"")) | H22: =IF($D22="","",IF($D22=H$8,$F22-$E22,"")) | I22: =IF($D22="","",IF($D22=I$8,$F22-$E22,"")) | J22: =IF($D22="","",IF($D22=CONCATENATE(J$7," ",J$8),$F22-$E22,"")) | K22: =IF($D22="","",IF($D22=CONCATENATE(J$7," ",K$8),$F22-$E22,"")) | N22: =IF($D22="","",IF($D22="PAX",$F22-$E22,"")) -> 0.0027777778 | O22: =IF(ISBLANK(F22), "", IF(W22=TRUE(),7,IF(V22=TRUE(),6,1))) -> 1 | P22: =IF($O22=P$9,F22-E22,"") -> 0.0027777778 | Q22: =IF($O22=6,F22-E22,"") | R22: =IF($O22=R$9,F22-E22,"") | U22: =IF($G$5=A22,"Max Launches","") | V22: =FALSE() -> FALSE | W22: =FALSE() -> FALSE
A23: 14 | G23: =IF($D23="","",IF($D23=G$8,$F23-$E23,"")) | H23: =IF($D23="","",IF($D23=H$8,$F23-$E23,"")) | I23: =IF($D23="","",IF($D23=I$8,$F23-$E23,"")) | J23: =IF($D23="","",IF($D23=CONCATENATE(J$7," ",J$8),$F23-$E23,"")) | K23: =IF($D23="","",IF($D23=CONCATENATE(J$7," ",K$8),$F23-$E23,"")) | N23: =IF($D23="","",IF($D23="PAX",$F23-$E23,"")) | O23: =IF(ISBLANK(F23), "", IF(W23=TRUE(),7,IF(V23=TRUE(),6,1))) | P23: =IF($O23=P$9,F23-E23,"") | Q23: =IF($O23=6,F23-E23,"") | R23: =IF($O23=R$9,F23-E23,"") | U23: =IF($G$5=A23,"Max Launches","") | V23: =FALSE() -> FALSE | W23: =FALSE() -> FALSE
A24: 15 | G24: =IF($D24="","",IF($D24=G$8,$F24-$E24,"")) | H24: =IF($D24="","",IF($D24=H$8,$F24-$E24,"")) | I24: =IF($D24="","",IF($D24=I$8,$F24-$E24,"")) | J24: =IF($D24="","",IF($D24=CONCATENATE(J$7," ",J$8),$F24-$E24,"")) | K24: =IF($D24="","",IF($D24=CONCATENATE(J$7," ",K$8),$F24-$E24,"")) | N24: =IF($D24="","",IF($D24="PAX",$F24-$E24,"")) | O24: =IF(ISBLANK(F24), "", IF(W24=TRUE(),7,IF(V24=TRUE(),6,1))) | P24: =IF($O24=P$9,F24-E24,"") | Q24: =IF($O24=6,F24-E24,"") | R24: =IF($O24=R$9,F24-E24,"") | U24: =IF($G$5=A24,"Max Launches","") | V24: =FALSE() -> FALSE | W24: =FALSE() -> FALSE
A25: 16 | G25: =IF($D25="","",IF($D25=G$8,$F25-$E25,"")) | H25: =IF($D25="","",IF($D25=H$8,$F25-$E25,"")) | I25: =IF($D25="","",IF($D25=I$8,$F25-$E25,"")) | J25: =IF($D25="","",IF($D25=CONCATENATE(J$7," ",J$8),$F25-$E25,"")) | K25: =IF($D25="","",IF($D25=CONCATENATE(J$7," ",K$8),$F25-$E25,"")) | N25: =IF($D25="","",IF($D25="PAX",$F25-$E25,"")) | O25: =IF(ISBLANK(F25), "", IF(W25=TRUE(),7,IF(V25=TRUE(),6,1))) | P25: =IF($O25=P$9,F25-E25,"") | Q25: =IF($O25=6,F25-E25,"") | R25: =IF($O25=R$9,F25-E25,"") | U25: =IF($G$5=A25,"Max Launches","") | V25: =FALSE() -> FALSE | W25: =FALSE() -> FALSE
A26: 17 | G26: =IF($D26="","",IF($D26=G$8,$F26-$E26,"")) | H26: =IF($D26="","",IF($D26=H$8,$F26-$E26,"")) | I26: =IF($D26="","",IF($D26=I$8,$F26-$E26,"")) | J26: =IF($D26="","",IF($D26=CONCATENATE(J$7," ",J$8),$F26-$E26,"")) | K26: =IF($D26="","",IF($D26=CONCATENATE(J$7," ",K$8),$F26-$E26,"")) | N26: =IF($D26="","",IF($D26="PAX",$F26-$E26,"")) | O26: =IF(ISBLANK(F26), "", IF(W26=TRUE(),7,IF(V26=TRUE(),6,1))) | P26: =IF($O26=P$9,F26-E26,"") | Q26: =IF($O26=6,F26-E26,"") | R26: =IF($O26=R$9,F26-E26,"") | U26: =IF($G$5=A26,"Max Launches","") | V26: =FALSE() -> FALSE | W26: =FALSE() -> FALSE
A27: 18 | G27: =IF($D27="","",IF($D27=G$8,$F27-$E27,"")) | H27: =IF($D27="","",IF($D27=H$8,$F27-$E27,"")) | I27: =IF($D27="","",IF($D27=I$8,$F27-$E27,"")) | J27: =IF($D27="","",IF($D27=CONCATENATE(J$7," ",J$8),$F27-$E27,"")) | K27: =IF($D27="","",IF($D27=CONCATENATE(J$7," ",K$8),$F27-$E27,"")) | N27: =IF($D27="","",IF($D27="PAX",$F27-$E27,"")) | O27: =IF(ISBLANK(F27), "", IF(W27=TRUE(),7,IF(V27=TRUE(),6,1))) | P27: =IF($O27=P$9,F27-E27,"") | Q27: =IF($O27=6,F27-E27,"") | R27: =IF($O27=R$9,F27-E27,"") | U27: =IF($G$5=A27,"Max Launches","") | V27: =FALSE() -> FALSE | W27: =FALSE() -> FALSE
A28: 19 | G28: =IF($D28="","",IF($D28=G$8,$F28-$E28,"")) | H28: =IF($D28="","",IF($D28=H$8,$F28-$E28,"")) | I28: =IF($D28="","",IF($D28=I$8,$F28-$E28,"")) | J28: =IF($D28="","",IF($D28=CONCATENATE(J$7," ",J$8),$F28-$E28,"")) | K28: =IF($D28="","",IF($D28=CONCATENATE(J$7," ",K$8),$F28-$E28,"")) | N28: =IF($D28="","",IF($D28="PAX",$F28-$E28,"")) | O28: =IF(ISBLANK(F28), "", IF(W28=TRUE(),7,IF(V28=TRUE(),6,1))) | P28: =IF($O28=P$9,F28-E28,"") | Q28: =IF($O28=6,F28-E28,"") | R28: =IF($O28=R$9,F28-E28,"") | U28: =IF($G$5=A28,"Max Launches","") | V28: =FALSE() -> FALSE | W28: =FALSE() -> FALSE
A29: 20 | G29: =IF($D29="","",IF($D29=G$8,$F29-$E29,"")) | H29: =IF($D29="","",IF($D29=H$8,$F29-$E29,"")) | I29: =IF($D29="","",IF($D29=I$8,$F29-$E29,"")) | J29: =IF($D29="","",IF($D29=CONCATENATE(J$7," ",J$8),$F29-$E29,"")) | K29: =IF($D29="","",IF($D29=CONCATENATE(J$7," ",K$8),$F29-$E29,"")) | N29: =IF($D29="","",IF($D29="PAX",$F29-$E29,"")) | O29: =IF(ISBLANK(F29), "", IF(W29=TRUE(),7,IF(V29=TRUE(),6,1))) | P29: =IF($O29=P$9,F29-E29,"") | Q29: =IF($O29=6,F29-E29,"") | R29: =IF($O29=R$9,F29-E29,"") | U29: =IF($G$5=A29,"Max Launches","") | V29: =FALSE() -> FALSE | W29: =FALSE() -> FALSE
A30: 21 | G30: =IF($D30="","",IF($D30=G$8,$F30-$E30,"")) | H30: =IF($D30="","",IF($D30=H$8,$F30-$E30,"")) | I30: =IF($D30="","",IF($D30=I$8,$F30-$E30,"")) | J30: =IF($D30="","",IF($D30=CONCATENATE(J$7," ",J$8),$F30-$E30,"")) | K30: =IF($D30="","",IF($D30=CONCATENATE(J$7," ",K$8),$F30-$E30,"")) | N30: =IF($D30="","",IF($D30="PAX",$F30-$E30,"")) | O30: =IF(ISBLANK(F30), "", IF(W30=TRUE(),7,IF(V30=TRUE(),6,1))) | P30: =IF($O30=P$9,F30-E30,"") | Q30: =IF($O30=6,F30-E30,"") | R30: =IF($O30=R$9,F30-E30,"") | U30: =IF($G$5=A30,"Max Launches","") | V30: =FALSE() -> FALSE | W30: =FALSE() -> FALSE
A31: 22 | G31: =IF($D31="","",IF($D31=G$8,$F31-$E31,"")) | H31: =IF($D31="","",IF($D31=H$8,$F31-$E31,"")) | I31: =IF($D31="","",IF($D31=I$8,$F31-$E31,"")) | J31: =IF($D31="","",IF($D31=CONCATENATE(J$7," ",J$8),$F31-$E31,"")) | K31: =IF($D31="","",IF($D31=CONCATENATE(J$7," ",K$8),$F31-$E31,"")) | N31: =IF($D31="","",IF($D31="PAX",$F31-$E31,"")) | O31: =IF(ISBLANK(F31), "", IF(W31=TRUE(),7,IF(V31=TRUE(),6,1))) | P31: =IF($O31=P$9,F31-E31,"") | Q31: =IF($O31=6,F31-E31,"") | R31: =IF($O31=R$9,F31-E31,"") | U31: =IF($G$5=A31,"Max Launches","") | V31: =FALSE() -> FALSE | W31: =FALSE() -> FALSE
A32: 23 | G32: =IF($D32="","",IF($D32=G$8,$F32-$E32,"")) | H32: =IF($D32="","",IF($D32=H$8,$F32-$E32,"")) | I32: =IF($D32="","",IF($D32=I$8,$F32-$E32,"")) | J32: =IF($D32="","",IF($D32=CONCATENATE(J$7," ",J$8),$F32-$E32,"")) | K32: =IF($D32="","",IF($D32=CONCATENATE(J$7," ",K$8),$F32-$E32,"")) | N32: =IF($D32="","",IF($D32="PAX",$F32-$E32,"")) | O32: =IF(ISBLANK(F32), "", IF(W32=TRUE(),7,IF(V32=TRUE(),6,1))) | P32: =IF($O32=P$9,F32-E32,"") | Q32: =IF($O32=6,F32-E32,"") | R32: =IF($O32=R$9,F32-E32,"") | U32: =IF($G$5=A32,"Max Launches","") | V32: =FALSE() -> FALSE | W32: =FALSE() -> FALSE
A33: 24 | G33: =IF($D33="","",IF($D33=G$8,$F33-$E33,"")) | H33: =IF($D33="","",IF($D33=H$8,$F33-$E33,"")) | I33: =IF($D33="","",IF($D33=I$8,$F33-$E33,"")) | J33: =IF($D33="","",IF($D33=CONCATENATE(J$7," ",J$8),$F33-$E33,"")) | K33: =IF($D33="","",IF($D33=CONCATENATE(J$7," ",K$8),$F33-$E33,"")) | N33: =IF($D33="","",IF($D33="PAX",$F33-$E33,"")) | O33: =IF(ISBLANK(F33), "", IF(W33=TRUE(),7,IF(V33=TRUE(),6,1))) | P33: =IF($O33=P$9,F33-E33,"") | Q33: =IF($O33=6,F33-E33,"") | R33: =IF($O33=R$9,F33-E33,"") | U33: =IF($G$5=A33,"Max Launches","") | V33: =FALSE() -> FALSE | W33: =FALSE() -> FALSE
A34: 25 | G34: =IF($D34="","",IF($D34=G$8,$F34-$E34,"")) | H34: =IF($D34="","",IF($D34=H$8,$F34-$E34,"")) | I34: =IF($D34="","",IF($D34=I$8,$F34-$E34,"")) | J34: =IF($D34="","",IF($D34=CONCATENATE(J$7," ",J$8),$F34-$E34,"")) | K34: =IF($D34="","",IF($D34=CONCATENATE(J$7," ",K$8),$F34-$E34,"")) | N34: =IF($D34="","",IF($D34="PAX",$F34-$E34,"")) | O34: =IF(ISBLANK(F34), "", IF(W34=TRUE(),7,IF(V34=TRUE(),6,1))) | P34: =IF($O34=P$9,F34-E34,"") | Q34: =IF($O34=6,F34-E34,"") | R34: =IF($O34=R$9,F34-E34,"") | U34: =IF($G$5=A34,"Max Launches","") | V34: =FALSE() -> FALSE | W34: =FALSE() -> FALSE
... A41: 32 | G41: =IF($D41="","",IF($D41=G$8,$F41-$E41,"")) | H41: =IF($D41="","",IF($D41=H$8,$F41-$E41,"")) | I41: =IF($D41="","",IF($D41=I$8,$F41-$E41,"")) | J41: =IF($D41="","",IF($D41=CONCATENATE(J$7," ",J$8),$F41-$E41,"")) | K41: =IF($D41="","",IF($D41=CONCATENATE(J$7," ",K$8),$F41-$E41,"")) | N41: =IF($D41="","",IF($D41="PAX",$F41-$E41,"")) | O41: =IF(ISBLANK(F41), "", IF(W41=TRUE(),7,IF(V41=TRUE(),6,1))) | P41: =IF($O41=P$9,F41-E41,"") | Q41: =IF($O41=6,F41-E41,"") | R41: =IF($O41=R$9,F41-E41,"") | U41: =IF($G$5=A41,"Max Launches","") | V41: =FALSE() -> FALSE | W41: =FALSE() -> FALSE
E42: Total Hours | G42: =IF(SUM(G10:G41)=0,"",SUM(G10:G41)) -> 0.022222222 | H42: =IF(SUM(H10:H41)=0,"",SUM(H10:H41)) | I42: =IF(SUM(I10:I41)=0,"",SUM(I10:I41)) -> 0.013194444 | J42: =IF(SUM(J10:J41)=0,"",SUM(J10:J41)) -> 0.0034722222 | K42: =IF(SUM(K10:K41)=0,"",SUM(K10:K41)) -> 0.0034722222 | L42: =IF(L$10="","",SUM(L10:L41)) | M42: =IF(M$10="","",SUM(M10:M41)) | N42: =IF(SUM(N10:N41)=0,"",SUM(N10:N41)) -> 0.0027777778 | P42: =IF(SUM(P10:P41)=0,"",SUM(P10:P41)) -> 0.035416667 | Q42: =IF(SUM(Q10:Q41)=0,"",SUM(Q10:Q41)) -> 0.0055555556 | R42: =IF(SUM(R10:R41)=0,"",SUM(R10:R41)) -> 0.0041666667
E43: Total Launches | G43: =IF(COUNT(G10:G41)=0,"",COUNT(G10:G41)) -> 6 | H43: =IF(COUNT(H10:H41)=0,"",COUNT(H10:H41)) | I43: =IF(COUNT(I10:I41)=0,"",COUNT(I10:I41)) -> 4 | J43: =IF(COUNT(J10:J41)=0,"",COUNT(J10:J41)) -> 1 | K43: =IF(COUNT(K10:K41)=0,"",COUNT(K10:K41)) -> 1 | L43: =IF(L$10="","",32-COUNTBLANK(L10:L41)) | M43: =IF(M$10="","",32-COUNTBLANK(M10:M41)) | N43: =IF(COUNT(N10:N41)=0,"",COUNT(N10:N41)) -> 1 | P43: =IF(COUNT(P10:P41)=0,"",COUNT(P10:P41)) -> 11 | Q43: =IF(COUNT(Q10:Q41)=0,"",COUNT(Q10:Q41)) -> 1 | R43: =IF(COUNT(R10:R41)=0,"",COUNT(R10:R41)) -> 1
G45: F724 Entries
G46: Hours Flown | K46: Launches | O46: Sortie Profile Code | S46: Captains Name
F47: Date | G47: Daily Total | I47: Total | K47: Daily Total | M47: Total
E48: Line 1 | F48: =IF(O48="","",O2) -> 46067 | G48: =IF(O48=1,P42,IF(O48=6,Q42,"")) | I48: =IF(G48="","",C4+G48) | K48: =IF(O48=1,P43,IF(O48=6,Q43,"")) | M48: =IF(K48="","",C5+K48) | O48: =IF($R$43<=32,7,IF($Q$43<=32,6,IF($P$43<=32,1,""))) -> 7 | S48: {=IFERROR(LOOKUP(2,1/(ISTEXT(B10:B41)), B10:B41), "")} -> Abbott
E49: =IF(O49=1,"Line 2","") | F49: =IF(O49="","",O2) | G49: =IF(O49=1,P42,"") | I49: =IF(G49="","",I48+G49) | K49: =IF(O49=1,P43,"") | M49: =IF(K49="","",M48+K49) | O49: =IF(AND(O48=6,P43<=32),1,"") | S49: =IF(O49=1,S48,"")

Sheet Print Copy
B2: RAF GLIDER DAILY FLYING TIMES | W2: RAF Form 2965B (Revised 1/19) PPQ = 100
C4: Unit 661VGS | D4: A/C Number | F4: =IF(ISBLANK(2965D!$F$2), "", 2965D!$F$2) -> ZE633 | H4: A/C Tail Letters | L4: =IF(ISBLANK(2965D!$L$2), "", 2965D!$L$2) -> XX | O4: Date | Q4: =IF(ISBLANK(2965D!$O$2),"",2965D!$O$2) -> 46067
B6: Ser No | C6: Aircraft Commander | D6: 2nd Pilot/ Trainee or Passenger | E6: Duty | F6: Take Off Time | G6: Landing Time | H6: Trainee | K6: SCT | M6: Claimed By | O6: Other (G) | P6: Sortie Profile Codes (SPC) (Hours/Minutes) | W6: Aero Tow | X6: PLF | Y6: After Flight initials
H7: ATP | I7: SGS | J7: GWGT | K7: QGI | L7: U/T
H8: (B) | I8: (C) | J8: (D) | K8: (E) | L8: (F) | M8: P1 | N8: P2 | P8: 1 | Q8: 2 | R8: 3 | S8: 4 | T8: 5 | U8: 6 | V8: 7
B9: 1 | C9: =2965D!B10 -> Jennings | D9: =2965D!C10 -> Smith | E9: =2965D!D10 -> GIF | F9: =2965D!E10 -> 0.45833333 | G9: =2965D!F10 -> 0.46388889 | H9: =IF(2965D!G10="","",2965D!G10) -> 0.0055555556 | I9: =IF(2965D!H10="","",2965D!H10) | J9: =IF(2965D!I10="","",2965D!I10) | K9: =IF(2965D!J10="","",2965D!J10) | L9: =IF(2965D!K10="","",2965D!K10) | M9: =IF(FORMATTED!K2=TRUE(),"ü","") | N9: =IF(FORMATTED!L2=TRUE(),"ü","") | O9: =IF(2965D!N10="","",2965D!N10) | P9: =IF(2965D!P10="","",2965D!P10) | U9: =IF(2965D!Q10="","",2965D!Q10) -> 0.0055555556 | V9: =IF(2965D!R10="","",2965D!R10) | X9: =IF(FORMATTED!H2=TRUE(),"ü","") | Y9: =IFERROR(VLOOKUP(2965D!T10,Pilots[[SN Last 4]:[Pilot]],2,FALSE()),"") | Z9: =IF(2965D!$G$5=B9,"Max","")
B10: 2 | C10: =2965D!B11 -> Jennings | D10: =2965D!C11 -> Smith | E10: =2965D!D11 -> GIF | F10: =2965D!E11 -> 0.46944444 | G10: =2965D!F11 -> 0.47291667 | H10: =IF(2965D!G11="","",2965D!G11) -> 0.0034722222 | I10: =IF(2965D!H11="","",2965D!H11) | J10: =IF(2965D!I11="","",2965D!I11) | K10: =IF(2965D!J11="","",2965D!J11) | L10: =IF(2965D!K11="","",2965D!K11) | M10: =IF(FORMATTED!K3=TRUE(),"ü","") | N10: =IF(FORMATTED!L3=TRUE(),"ü","") | O10: =IF(2965D!N11="","",2965D!N11) | P10: =IF(2965D!P11="","",2965D!P11) -> 0.0034722222 | U10: =IF(2965D!Q11="","",2965D!Q11) | V10: =IF(2965D!R11="","",2965D!R11) | X10: =IF(FORMATTED!H3=TRUE(),"ü","") | Y10: =IFERROR(VLOOKUP(2965D!T11,Pilots[[SN Last 4]:[Pilot]],2,FALSE()),"") | Z10: =IF(2965D!$G$5=B10,"Max",IF(2965D!$G$5=B9,"Launches",""))
B11: 3 | C11: =2965D!B12 -> Jennings | D11: =2965D!C12 -> Derp | E11: =2965D!D12 -> GIF | F11: =2965D!E12 -> 0.47777778 | G11: =2965D!F12 -> 0.48125 | H11: =IF(2965D!G12="","",2965D!G12) -> 0.0034722222 | I11: =IF(2965D!H12="","",2965D!H12) | J11: =IF(2965D!I12="","",2965D!I12) | K11: =IF(2965D!J12="","",2965D!J12) | L11: =IF(2965D!K12="","",2965D!K12) | M11: =IF(FORMATTED!K4=TRUE(),"ü","") | N11: =IF(FORMATTED!L4=TRUE(),"ü","") | O11: =IF(2965D!N12="","",2965D!N12) | P11: =IF(2965D!P12="","",2965D!P12) -> 0.0034722222 | U11: =IF(2965D!Q12="","",2965D!Q12) | V11: =IF(2965D!R12="","",2965D!R12) | X11: =IF(FORMATTED!H4=TRUE(),"ü","") | Y11: =IFERROR(VLOOKUP(2965D!T12,Pilots[[SN Last 4]:[Pilot]],2,FALSE()),"") | Z11: =IF(2965D!$G$5=B11,"Max",IF(2965D!$G$5=B10,"Launches","")) | AA11: Print Instructions
B12: 4 | C12: =2965D!B13 -> Jennings | D12: =2965D!C13 -> Derp | E12: =2965D!D13 -> GIF | F12: =2965D!E13 -> 0.48611111 | G12: =2965D!F13 -> 0.48888889 | H12: =IF(2965D!G13="","",2965D!G13) -> 0.0027777778 | I12: =IF(2965D!H13="","",2965D!H13) | J12: =IF(2965D!I13="","",2965D!I13) | K12: =IF(2965D!J13="","",2965D!J13) | L12: =IF(2965D!K13="","",2965D!K13) | M12: =IF(FORMATTED!K5=TRUE(),"ü","") | N12: =IF(FORMATTED!L5=TRUE(),"ü","") | O12: =IF(2965D!N13="","",2965D!N13) | P12: =IF(2965D!P13="","",2965D!P13) -> 0.0027777778 | U12: =IF(2965D!Q13="","",2965D!Q13) | V12: =IF(2965D!R13="","",2965D!R13) | X12: =IF(FORMATTED!H5=TRUE(),"ü","") | Y12: =IFERROR(VLOOKUP(2965D!T13,Pilots[[SN Last 4]:[Pilot]],2,FALSE()),"") | Z12: =IF(2965D!$G$5=B12,"Max",IF(2965D!$G$5=B11,"Launches","")) | AA12: File -> Print
B13: 5 | C13: =2965D!B14 -> Jennings | D13: =2965D!C14 -> Bojangles | E13: =2965D!D14 -> GIF | F13: =2965D!E14 -> 0.49444444 | G13: =2965D!F14 -> 0.49861111 | H13: =IF(2965D!G14="","",2965D!G14) -> 0.0041666667 | I13: =IF(2965D!H14="","",2965D!H14) | J13: =IF(2965D!I14="","",2965D!I14) | K13: =IF(2965D!J14="","",2965D!J14) | L13: =IF(2965D!K14="","",2965D!K14) | M13: =IF(FORMATTED!K6=TRUE(),"ü","") | N13: =IF(FORMATTED!L6=TRUE(),"ü","") | O13: =IF(2965D!N14="","",2965D!N14) | P13: =IF(2965D!P14="","",2965D!P14) | U13: =IF(2965D!Q14="","",2965D!Q14) | V13: =IF(2965D!R14="","",2965D!R14) -> 0.0041666667 | X13: =IF(FORMATTED!H6=TRUE(),"ü","") | Y13: =IFERROR(VLOOKUP(2965D!T14,Pilots[[SN Last 4]:[Pilot]],2,FALSE()),"") | Z13: =IF(2965D!$G$5=B13,"Max",IF(2965D!$G$5=B12,"Launches","")) | AA13: Print only active sheet
B14: 6 | C14: =2965D!B15 -> Jennings | D14: =2965D!C15 -> Bojangles | E14: =2965D!D15 -> GIF | F14: =2965D!E15 -> 0.50347222 | G14: =2965D!F15 -> 0.50625 | H14: =IF(2965D!G15="","",2965D!G15) -> 0.0027777778 | I14: =IF(2965D!H15="","",2965D!H15) | J14: =IF(2965D!I15="","",2965D!I15) | K14: =IF(2965D!J15="","",2965D!J15) | L14: =IF(2965D!K15="","",2965D!K15) | M14: =IF(FORMATTED!K7=TRUE(),"ü","") | N14: =IF(FORMATTED!L7=TRUE(),"ü","") | O14: =IF(2965D!N15="","",2965D!N15) | P14: =IF(2965D!P15="","",2965D!P15) -> 0.0027777778 | U14: =IF(2965D!Q15="","",2965D!Q15) | V14: =IF(2965D!R15="","",2965D!R15) | X14: =IF(FORMATTED!H7=TRUE(),"ü","") -> ü | Y14: =IFERROR(VLOOKUP(2965D!T15,Pilots[[SN Last 4]:[Pilot]],2,FALSE()),"") | Z14: =IF(2965D!$G$5=B14,"Max",IF(2965D!$G$5=B13,"Launches","")) | AA14: Double sided flip on long side
B15: 7 | C15: =2965D!B16 -> Jennings | D15: =2965D!C16 -> Bloggs | E15: =2965D!D16 -> AGT | F15: =2965D!E16 -> 0.62638889 | G15: =2965D!F16 -> 0.62916667 | H15: =IF(2965D!G16="","",2965D!G16) | I15: =IF(2965D!H16="","",2965D!H16) | J15: =IF(2965D!I16="","",2965D!I16) -> 0.0027777778 | K15: =IF(2965D!J16="","",2965D!J16) | L15: =IF(2965D!K16="","",2965D!K16) | M15: =IF(FORMATTED!K8=TRUE(),"ü","") | N15: =IF(FORMATTED!L8=TRUE(),"ü","") | O15: =IF(2965D!N16="","",2965D!N16) | P15: =IF(2965D!P16="","",2965D!P16) -> 0.0027777778 | U15: =IF(2965D!Q16="","",2965D!Q16) | V15: =IF(2965D!R16="","",2965D!R16) | X15: =IF(FORMATTED!H8=TRUE(),"ü","") | Y15: =IFERROR(VLOOKUP(2965D!T16,Pilots[[SN Last 4]:[Pilot]],2,FALSE()),"") | Z15: =IF(2965D!$G$5=B15,"Max",IF(2965D!$G$5=B14,"Launches",""))
B16: 8 | C16: =2965D!B17 -> Jennings | D16: =2965D!C17 -> Bloggs | E16: =2965D!D17 -> AGT | F16: =2965D!E17 -> 0.63611111 | G16: =2965D!F17 -> 0.63958333 | H16: =IF(2965D!G17="","",2965D!G17) | I16: =IF(2965D!H17="","",2965D!H17) | J16: =IF(2965D!I17="","",2965D!I17) -> 0.0034722222 | K16: =IF(2965D!J17="","",2965D!J17) | L16: =IF(2965D!K17="","",2965D!K17) | M16: =IF(FORMATTED!K9=TRUE(),"ü","") | N16: =IF(FORMATTED!L9=TRUE(),"ü","") | O16: =IF(2965D!N17="","",2965D!N17) | P16: =IF(2965D!P17="","",2965D!P17) -> 0.0034722222 | U16: =IF(2965D!Q17="","",2965D!Q17) | V16: =IF(2965D!R17="","",2965D!R17) | X16: =IF(FORMATTED!H9=TRUE(),"ü","") | Y16: =IFERROR(VLOOKUP(2965D!T17,Pilots[[SN Last 4]:[Pilot]],2,FALSE()),"") | Z16: =IF(2965D!$G$5=B16,"Max",IF(2965D!$G$5=B15,"Launches",""))
B17: 9 | C17: =2965D!B18 -> Jennings | D17: =2965D!C18 -> Bloggs | E17: =2965D!D18 -> AGT | F17: =2965D!E18 -> 0.64513889 | G17: =2965D!F18 -> 0.64861111 | H17: =IF(2965D!G18="","",2965D!G18) | I17: =IF(2965D!H18="","",2965D!H18) | J17: =IF(2965D!I18="","",2965D!I18) -> 0.0034722222 | K17: =IF(2965D!J18="","",2965D!J18) | L17: =IF(2965D!K18="","",2965D!K18) | M17: =IF(FORMATTED!K10=TRUE(),"ü","") | N17: =IF(FORMATTED!L10=TRUE(),"ü","") | O17: =IF(2965D!N18="","",2965D!N18) | P17: =IF(2965D!P18="","",2965D!P18) -> 0.0034722222 | U17: =IF(2965D!Q18="","",2965D!Q18) | V17: =IF(2965D!R18="","",2965D!R18) | X17: =IF(FORMATTED!H10=TRUE(),"ü","") | Y17: =IFERROR(VLOOKUP(2965D!T18,Pilots[[SN Last 4]:[Pilot]],2,FALSE()),"") | Z17: =IF(2965D!$G$5=B17,"Max",IF(2965D!$G$5=B16,"Launches",""))
B18: 10 | C18: =2965D!B19 -> Jennings | D18: =2965D!C19 -> Bloggs | E18: =2965D!D19 -> AGT | F18: =2965D!E19 -> 0.65625 | G18: =2965D!F19 -> 0.65972222 | H18: =IF(2965D!G19="","",2965D!G19) | I18: =IF(2965D!H19="","",2965D!H19) | J18: =IF(2965D!I19="","",2965D!I19) -> 0.0034722222 | K18: =IF(2965D!J19="","",2965D!J19) | L18: =IF(2965D!K19="","",2965D!K19) | M18: =IF(FORMATTED!K11=TRUE(),"ü","") | N18: =IF(FORMATTED!L11=TRUE(),"ü","") | O18: =IF(2965D!N19="","",2965D!N19) | P18: =IF(2965D!P19="","",2965D!P19) -> 0.0034722222 | U18: =IF(2965D!Q19="","",2965D!Q19) | V18: =IF(2965D!R19="","",2965D!R19) | X18: =IF(FORMATTED!H11=TRUE(),"ü","") | Y18: =IFERROR(VLOOKUP(2965D!T19,Pilots[[SN Last 4]:[Pilot]],2,FALSE()),"") | Z18: =IF(2965D!$G$5=B18,"Max",IF(2965D!$G$5=B17,"Launches",""))
B19: 11 | C19: =2965D!B20 -> Abbott | D19: =2965D!C20 -> Bloggs | E19: =2965D!D20 -> SCT QGI | F19: =2965D!E20 -> 0.66875 | G19: =2965D!F20 -> 0.67222222 | H19: =IF(2965D!G20="","",2965D!G20) | I19: =IF(2965D!H20="","",2965D!H20) | J19: =IF(2965D!I20="","",2965D!I20) | K19: =IF(2965D!J20="","",2965D!J20) -> 0.0034722222 | L19: =IF(2965D!K20="","",2965D!K20) | M19: =IF(FORMATTED!K12=TRUE(),"ü","") -> ü | N19: =IF(FORMATTED!L12=TRUE(),"ü","") | O19: =IF(2965D!N20="","",2965D!N20) | P19: =IF(2965D!P20="","",2965D!P20) -> 0.0034722222 | U19: =IF(2965D!Q20="","",2965D!Q20) | V19: =IF(2965D!R20="","",2965D!R20) | X19: =IF(FORMATTED!H12=TRUE(),"ü","") | Y19: =IFERROR(VLOOKUP(2965D!T20,Pilots[[SN Last 4]:[Pilot]],2,FALSE()),"") | Z19: =IF(2965D!$G$5=B19,"Max",IF(2965D!$G$5=B18,"Launches",""))
B20: 12 | C20: =2965D!B21 -> Abbott | D20: =2965D!C21 -> Bloggs | E20: =2965D!D21 -> SCT U/T | F20: =2965D!E21 -> 0.68055556 | G20: =2965D!F21 -> 0.68402778 | H20: =IF(2965D!G21="","",2965D!G21) | I20: =IF(2965D!H21="","",2965D!H21) | J20: =IF(2965D!I21="","",2965D!I21) | K20: =IF(2965D!J21="","",2965D!J21) | L20: =IF(2965D!K21="","",2965D!K21) -> 0.0034722222 | M20: =IF(FORMATTED!K13=TRUE(),"ü","") | N20: =IF(FORMATTED!L13=TRUE(),"ü","") -> ü | O20: =IF(2965D!N21="","",2965D!N21) | P20: =IF(2965D!P21="","",2965D!P21) -> 0.0034722222 | U20: =IF(2965D!Q21="","",2965D!Q21) | V20: =IF(2965D!R21="","",2965D!R21) | X20: =IF(FORMATTED!H13=TRUE(),"ü","") | Y20: =IFERROR(VLOOKUP(2965D!T21,Pilots[[SN Last 4]:[Pilot]],2,FALSE()),"") | Z20: =IF(2965D!$G$5=B20,"Max",IF(2965D!$G$5=B19,"Launches",""))
B21: 13 | C21: =2965D!B22 -> Abbott | D21: =2965D!C22 -> Bloggs | E21: =2965D!D22 -> PAX | F21: =2965D!E22 -> 0.69027778 | G21: =2965D!F22 -> 0.69305556 | H21: =IF(2965D!G22="","",2965D!G22) | I21: =IF(2965D!H22="","",2965D!H22) | J21: =IF(2965D!I22="","",2965D!I22) | K21: =IF(2965D!J22="","",2965D!J22) | L21: =IF(2965D!K22="","",2965D!K22) | M21: =IF(FORMATTED!K14=TRUE(),"ü","") | N21: =IF(FORMATTED!L14=TRUE(),"ü","") | O21: =IF(2965D!N22="","",2965D!N22) -> 0.0027777778 | P21: =IF(2965D!P22="","",2965D!P22) -> 0.0027777778 | U21: =IF(2965D!Q22="","",2965D!Q22) | V21: =IF(2965D!R22="","",2965D!R22) | X21: =IF(FORMATTED!H14=TRUE(),"ü","") | Y21: =IFERROR(VLOOKUP(2965D!T22,Pilots[[SN Last 4]:[Pilot]],2,FALSE()),"") | Z21: =IF(2965D!$G$5=B21,"Max",IF(2965D!$G$5=B20,"Launches",""))
B22: 14 | C22: =2965D!B23 -> 0 | D22: =2965D!C23 -> 0 | E22: =2965D!D23 -> 0 | F22: =2965D!E23 -> 0 | G22: =2965D!F23 -> 0 | H22: =IF(2965D!G23="","",2965D!G23) | I22: =IF(2965D!H23="","",2965D!H23) | J22: =IF(2965D!I23="","",2965D!I23) | K22: =IF(2965D!J23="","",2965D!J23) | L22: =IF(2965D!K23="","",2965D!K23) | M22: =IF(FORMATTED!K15=TRUE(),"ü","") | N22: =IF(FORMATTED!L15=TRUE(),"ü","") | O22: =IF(2965D!N23="","",2965D!N23) | P22: =IF(2965D!P23="","",2965D!P23) | U22: =IF(2965D!Q23="","",2965D!Q23) | V22: =IF(2965D!R23="","",2965D!R23) | X22: =IF(FORMATTED!H15=TRUE(),"ü","") | Y22: =IFERROR(VLOOKUP(2965D!T23,Pilots[[SN Last 4]:[Pilot]],2,FALSE()),"") | Z22: =IF(2965D!$G$5=B22,"Max",IF(2965D!$G$5=B21,"Launches",""))
B23: 15 | C23: =2965D!B24 -> 0 | D23: =2965D!C24 -> 0 | E23: =2965D!D24 -> 0 | F23: =2965D!E24 -> 0 | G23: =2965D!F24 -> 0 | H23: =IF(2965D!G24="","",2965D!G24) | I23: =IF(2965D!H24="","",2965D!H24) | J23: =IF(2965D!I24="","",2965D!I24) | K23: =IF(2965D!J24="","",2965D!J24) | L23: =IF(2965D!K24="","",2965D!K24) | M23: =IF(FORMATTED!K16=TRUE(),"ü","") | N23: =IF(FORMATTED!L16=TRUE(),"ü","") | O23: =IF(2965D!N24="","",2965D!N24) | P23: =IF(2965D!P24="","",2965D!P24) | U23: =IF(2965D!Q24="","",2965D!Q24) | V23: =IF(2965D!R24="","",2965D!R24) | X23: =IF(FORMATTED!H16=TRUE(),"ü","") | Y23: =IFERROR(VLOOKUP(2965D!T24,Pilots[[SN Last 4]:[Pilot]],2,FALSE()),"") | Z23: =IF(2965D!$G$5=B23,"Max",IF(2965D!$G$5=B22,"Launches",""))
B24: 16 | C24: =2965D!B25 -> 0 | D24: =2965D!C25 -> 0 | E24: =2965D!D25 -> 0 | F24: =2965D!E25 -> 0 | G24: =2965D!F25 -> 0 | H24: =IF(2965D!G25="","",2965D!G25) | I24: =IF(2965D!H25="","",2965D!H25) | J24: =IF(2965D!I25="","",2965D!I25) | K24: =IF(2965D!J25="","",2965D!J25) | L24: =IF(2965D!K25="","",2965D!K25) | M24: =IF(FORMATTED!K17=TRUE(),"ü","") | N24: =IF(FORMATTED!L17=TRUE(),"ü","") | O24: =IF(2965D!N25="","",2965D!N25) | P24: =IF(2965D!P25="","",2965D!P25) | U24: =IF(2965D!Q25="","",2965D!Q25) | V24: =IF(2965D!R25="","",2965D!R25) | X24: =IF(FORMATTED!H17=TRUE(),"ü","") | Y24: =IFERROR(VLOOKUP(2965D!T25,Pilots[[SN Last 4]:[Pilot]],2,FALSE()),"") | Z24: =IF(2965D!$G$5=B24,"Max",IF(2965D!$G$5=B23,"Launches",""))
B25: 17 | C25: =2965D!B26 -> 0 | D25: =2965D!C26 -> 0 | E25: =2965D!D26 -> 0 | F25: =2965D!E26 -> 0 | G25: =2965D!F26 -> 0 | H25: =IF(2965D!G26="","",2965D!G26) | I25: =IF(2965D!H26="","",2965D!H26) | J25: =IF(2965D!I26="","",2965D!I26) | K25: =IF(2965D!J26="","",2965D!J26) | L25: =IF(2965D!K26="","",2965D!K26) | M25: =IF(FORMATTED!K18=TRUE(),"ü","") | N25: =IF(FORMATTED!L18=TRUE(),"ü","") | O25: =IF(2965D!N26="","",2965D!N26) | P25: =IF(2965D!P26="","",2965D!P26) | U25: =IF(2965D!Q26="","",2965D!Q26) | V25: =IF(2965D!R26="","",2965D!R26) | X25: =IF(FORMATTED!H18=TRUE(),"ü","") | Y25: =IFERROR(VLOOKUP(2965D!T26,Pilots[[SN Last 4]:[Pilot]],2,FALSE()),"") | Z25: =IF(2965D!$G$5=B25,"Max",IF(2965D!$G$5=B24,"Launches",""))
B26: 18 | C26: =2965D!B27 -> 0 | D26: =2965D!C27 -> 0 | E26: =2965D!D27 -> 0 | F26: =2965D!E27 -> 0 | G26: =2965D!F27 -> 0 | H26: =IF(2965D!G27="","",2965D!G27) | I26: =IF(2965D!H27="","",2965D!H27) | J26: =IF(2965D!I27="","",2965D!I27) | K26: =IF(2965D!J27="","",2965D!J27) | L26: =IF(2965D!K27="","",2965D!K27) | M26: =IF(FORMATTED!K19=TRUE(),"ü","") | N26: =IF(FORMATTED!L19=TRUE(),"ü","") | O26: =IF(2965D!N27="","",2965D!N27) | P26: =IF(2965D!P27="","",2965D!P27) | U26: =IF(2965D!Q27="","",2965D!Q27) | V26: =IF(2965D!R27="","",2965D!R27) | X26: =IF(FORMATTED!H19=TRUE(),"ü","") | Y26: =IFERROR(VLOOKUP(2965D!T27,Pilots[[SN Last 4]:[Pilot]],2,FALSE()),"") | Z26: =IF(2965D!$G$5=B26,"Max",IF(2965D!$G$5=B25,"Launches",""))
... B28: 20 | C28: =2965D!B29 -> 0 | D28: =2965D!C29 -> 0 | E28: =2965D!D29 -> 0 | F28: =2965D!E29 -> 0 | G28: =2965D!F29 -> 0 | H28: =IF(2965D!G29="","",2965D!G29) | I28: =IF(2965D!H29="","",2965D!H29) | J28: =IF(2965D!I29="","",2965D!I29) | K28: =IF(2965D!J29="","",2965D!J29) | L28: =IF(2965D!K29="","",2965D!K29) | M28: =IF(FORMATTED!K21=TRUE(),"ü","") | N28: =IF(FORMATTED!L21=TRUE(),"ü","") | O28: =IF(2965D!N29="","",2965D!N29) | P28: =IF(2965D!P29="","",2965D!P29) | U28: =IF(2965D!Q29="","",2965D!Q29) | V28: =IF(2965D!R29="","",2965D!R29) | X28: =IF(FORMATTED!H21=TRUE(),"ü","") | Y28: =IFERROR(VLOOKUP(2965D!T29,Pilots[[SN Last 4]:[Pilot]],2,FALSE()),"") | Z28: =IF(2965D!$G$5=B28,"Max",IF(2965D!$G$5=B27,"Launches",""))
B29: SORTIE PROFILE CODES (SPC) 1. Winch launch with circuits 2. Aerotow 3. Aerotow with soaring 4. Aerotow with stalls 5. Aerotow with aerobatics 6. Winch launch with soaring 7. Winch launch with aerobatics | F29: Carry Forward | G29: Hours | H29: =SUM(H9:H28) -> 0.022222222 | I29: =SUM(I9:I28) -> 0 | J29: =SUM(J9:J28) -> 0.013194444 | K29: =SUM(K9:K28) -> 0.0034722222 | L29: =SUM(L9:L28) -> 0.0034722222 | O29: =SUM(O9:O28) -> 0.0027777778 | P29: =SUM(P9:P28) -> 0.035416667 | U29: =SUM(U9:U28) -> 0.0055555556 | V29: =SUM(V9:V28) -> 0.0041666667 | Z29: =IF(2965D!$G$5=B29,"Max",IF(2965D!$G$5=B28,"Launches",""))
G30: Launches | H30: =COUNT(H9:H28) -> 6 | I30: =COUNT(I9:I28) -> 0 | J30: =COUNT(J9:J28) -> 4 | K30: =COUNT(K9:K28) -> 1 | L30: =COUNT(L9:L28) -> 1 | O30: =COUNT(O9:O28) -> 1 | P30: =COUNT(P9:P28) -> 11 | U30: =COUNT(U9:U28) -> 1 | V30: =COUNT(V9:V28) -> 1
C38: Unit 661VGS | D38: A/C Number | F38: =IF(ISBLANK(2965D!$F$2), "", 2965D!$F$2) -> ZE633 | H38: A/C Tail Letters | L38: =IF(ISBLANK(2965D!$L$2), "", 2965D!$L$2) -> XX | O38: Date | Q38: =IF(ISBLANK(2965D!$O$2),"",2965D!$O$2) -> 46067
B40: Ser No | C40: Aircraft Commander | D40: 2nd Pilot/ Trainee or Passenger | E40: Duty | F40: Take Off Time | G40: Landing Time | H40: Trainee | K40: SCT | M40: Claimed By | O40: Other (G) | P40: Sortie Profile Codes (SPC) (Hours/Minutes) | W40: Aero Tow | X40: PLF | Y40: After Flight initials
H41: ATP | I41: SGS | J41: GWGT | K41: QGI | L41: U/T
H42: (B) | I42: (C) | J42: (D) | K42: (E) | L42: (F) | M42: P1 | N42: P2 | P42: 1 | Q42: 2 | R42: 3 | S42: 4 | T42: 5 | U42: 6 | V42: 7
B43: Brought Forward | G43: Hours | H43: =H29 -> 0.022222222 | I43: =I29 -> 0 | J43: =J29 -> 0.013194444 | K43: =K29 -> 0.0034722222 | L43: =L29 -> 0.0034722222 | O43: =O29 -> 0.0027777778 | P43: =P29 -> 0.035416667 | U43: =U29 -> 0.0055555556 | V43: =V29 -> 0.0041666667
G44: Launches | H44: =IF(H30="","",H30) -> 6 | I44: =IF(I30="","",I30) -> 0 | J44: =IF(J30="","",J30) -> 4 | K44: =IF(K30="","",K30) -> 1 | L44: =IF(L30="","",L30) -> 1 | O44: =IF(O30="","",O30) -> 1 | P44: =IF(P30="","",P30) -> 11 | Q44: =IF(Q30="","",Q30) | R44: =IF(R30="","",R30) | S44: =IF(S30="","",S30) | T44: =IF(T30="","",T30) | U44: =IF(U30="","",U30) -> 1 | V44: =IF(V30="","",V30) -> 1
B45: 21 | C45: =2965D!B30 -> 0 | D45: =2965D!C30 -> 0 | E45: =2965D!D30 -> 0 | F45: =2965D!E30 -> 0 | G45: =2965D!F30 -> 0 | H45: =IF(2965D!G30="","",2965D!G30) | I45: =IF(2965D!H30="","",2965D!H30) | J45: =IF(2965D!I30="","",2965D!I30) | K45: =IF(2965D!J30="","",2965D!J30) | L45: =IF(2965D!K30="","",2965D!K30) | M45: =IF(FORMATTED!K22=TRUE(),"ü","") | N45: =IF(FORMATTED!L22=TRUE(),"ü","") | O45: =IF(2965D!N30="","",2965D!N30) | P45: =IF(2965D!P30="","",2965D!P30) | U45: =IF(2965D!Q30="","",2965D!Q30) | V45: =IF(2965D!R30="","",2965D!R30) | X45: =IF(FORMATTED!H22=TRUE(),"ü","") | Y45: =IFERROR(VLOOKUP(2965D!T30,Pilots[[SN Last 4]:[Pilot]],2,FALSE()),"") | Z45: =IF(2965D!$G$5=B45,"Max","")
B46: 22 | C46: =2965D!B31 -> 0 | D46: =2965D!C31 -> 0 | E46: =2965D!D31 -> 0 | F46: =2965D!E31 -> 0 | G46: =2965D!F31 -> 0 | H46: =IF(2965D!G31="","",2965D!G31) | I46: =IF(2965D!H31="","",2965D!H31) | J46: =IF(2965D!I31="","",2965D!I31) | K46: =IF(2965D!J31="","",2965D!J31) | L46: =IF(2965D!K31="","",2965D!K31) | M46: =IF(FORMATTED!K23=TRUE(),"ü","") | N46: =IF(FORMATTED!L23=TRUE(),"ü","") | O46: =IF(2965D!N31="","",2965D!N31) | P46: =IF(2965D!P31="","",2965D!P31) | U46: =IF(2965D!Q31="","",2965D!Q31) | V46: =IF(2965D!R31="","",2965D!R31) | X46: =IF(FORMATTED!H23=TRUE(),"ü","") | Y46: =IFERROR(VLOOKUP(2965D!T31,Pilots[[SN Last 4]:[Pilot]],2,FALSE()),"") | Z46: =IF(2965D!$G$5=B46,"Max",IF(2965D!$G$5=B45,"Launches",""))
B47: 23 | C47: =2965D!B32 -> 0 | D47: =2965D!C32 -> 0 | E47: =2965D!D32 -> 0 | F47: =2965D!E32 -> 0 | G47: =2965D!F32 -> 0 | H47: =IF(2965D!G32="","",2965D!G32) | I47: =IF(2965D!H32="","",2965D!H32) | J47: =IF(2965D!I32="","",2965D!I32) | K47: =IF(2965D!J32="","",2965D!J32) | L47: =IF(2965D!K32="","",2965D!K32) | M47: =IF(FORMATTED!K24=TRUE(),"ü","") | N47: =IF(FORMATTED!L24=TRUE(),"ü","") | O47: =IF(2965D!N32="","",2965D!N32) | P47: =IF(2965D!P32="","",2965D!P32) | U47: =IF(2965D!Q32="","",2965D!Q32) | V47: =IF(2965D!R32="","",2965D!R32) | X47: =IF(FORMATTED!H24=TRUE(),"ü","") | Y47: =IFERROR(VLOOKUP(2965D!T32,Pilots[[SN Last 4]:[Pilot]],2,FALSE()),"") | Z47: =IF(2965D!$G$5=B47,"Max",IF(2965D!$G$5=B46,"Launches",""))
B48: 24 | C48: =2965D!B33 -> 0 | D48: =2965D!C33 -> 0 | E48: =2965D!D33 -> 0 | F48: =2965D!E33 -> 0 | G48: =2965D!F33 -> 0 | H48: =IF(2965D!G33="","",2965D!G33) | I48: =IF(2965D!H33="","",2965D!H33) | J48: =IF(2965D!I33="","",2965D!I33) | K48: =IF(2965D!J33="","",2965D!J33) | L48: =IF(2965D!K33="","",2965D!K33) | M48: =IF(FORMATTED!K25=TRUE(),"ü","") | N48: =IF(FORMATTED!L25=TRUE(),"ü","") | O48: =IF(2965D!N33="","",2965D!N33) | P48: =IF(2965D!P33="","",2965D!P33) | U48: =IF(2965D!Q33="","",2965D!Q33) | V48: =IF(2965D!R33="","",2965D!R33) | X48: =IF(FORMATTED!H25=TRUE(),"ü","") | Y48: =IFERROR(VLOOKUP(2965D!T33,Pilots[[SN Last 4]:[Pilot]],2,FALSE()),"") | Z48: =IF(2965D!$G$5=B48,"Max",IF(2965D!$G$5=B47,"Launches",""))
B49: 25 | C49: =2965D!B34 -> 0 | D49: =2965D!C34 -> 0 | E49: =2965D!D34 -> 0 | F49: =2965D!E34 -> 0 | G49: =2965D!F34 -> 0 | H49: =IF(2965D!G34="","",2965D!G34) | I49: =IF(2965D!H34="","",2965D!H34) | J49: =IF(2965D!I34="","",2965D!I34) | K49: =IF(2965D!J34="","",2965D!J34) | L49: =IF(2965D!K34="","",2965D!K34) | M49: =IF(FORMATTED!K26=TRUE(),"ü","") | N49: =IF(FORMATTED!L26=TRUE(),"ü","") | O49: =IF(2965D!N34="","",2965D!N34) | P49: =IF(2965D!P34="","",2965D!P34) | U49: =IF(2965D!Q34="","",2965D!Q34) | V49: =IF(2965D!R34="","",2965D!R34) | X49: =IF(FORMATTED!H26=TRUE(),"ü","") | Y49: =IFERROR(VLOOKUP(2965D!T34,Pilots[[SN Last 4]:[Pilot]],2,FALSE()),"") | Z49: =IF(2965D!$G$5=B49,"Max",IF(2965D!$G$5=B48,"Launches",""))
B50: 26 | C50: =2965D!B35 -> 0 | D50: =2965D!C35 -> 0 | E50: =2965D!D35 -> 0 | F50: =2965D!E35 -> 0 | G50: =2965D!F35 -> 0 | H50: =IF(2965D!G35="","",2965D!G35) | I50: =IF(2965D!H35="","",2965D!H35) | J50: =IF(2965D!I35="","",2965D!I35) | K50: =IF(2965D!J35="","",2965D!J35) | L50: =IF(2965D!K35="","",2965D!K35) | M50: =IF(FORMATTED!K27=TRUE(),"ü","") | N50: =IF(FORMATTED!L27=TRUE(),"ü","") | O50: =IF(2965D!N35="","",2965D!N35) | P50: =IF(2965D!P35="","",2965D!P35) | U50: =IF(2965D!Q35="","",2965D!Q35) | V50: =IF(2965D!R35="","",2965D!R35) | X50: =IF(FORMATTED!H27=TRUE(),"ü","") | Y50: =IFERROR(VLOOKUP(2965D!T35,Pilots[[SN Last 4]:[Pilot]],2,FALSE()),"") | Z50: =IF(2965D!$G$5=B50,"Max",IF(2965D!$G$5=B49,"Launches",""))
B51: 27 | C51: =2965D!B36 -> 0 | D51: =2965D!C36 -> 0 | E51: =2965D!D36 -> 0 | F51: =2965D!E36 -> 0 | G51: =2965D!F36 -> 0 | H51: =IF(2965D!G36="","",2965D!G36) | I51: =IF(2965D!H36="","",2965D!H36) | J51: =IF(2965D!I36="","",2965D!I36) | K51: =IF(2965D!J36="","",2965D!J36) | L51: =IF(2965D!K36="","",2965D!K36) | M51: =IF(FORMATTED!K28=TRUE(),"ü","") | N51: =IF(FORMATTED!L28=TRUE(),"ü","") | O51: =IF(2965D!N36="","",2965D!N36) | P51: =IF(2965D!P36="","",2965D!P36) | U51: =IF(2965D!Q36="","",2965D!Q36) | V51: =IF(2965D!R36="","",2965D!R36) | X51: =IF(FORMATTED!H28=TRUE(),"ü","") | Y51: =IFERROR(VLOOKUP(2965D!T36,Pilots[[SN Last 4]:[Pilot]],2,FALSE()),"") | Z51: =IF(2965D!$G$5=B51,"Max",IF(2965D!$G$5=B50,"Launches",""))
B52: 28 | C52: =2965D!B37 -> 0 | D52: =2965D!C37 -> 0 | E52: =2965D!D37 -> 0 | F52: =2965D!E37 -> 0 | G52: =2965D!F37 -> 0 | H52: =IF(2965D!G37="","",2965D!G37) | I52: =IF(2965D!H37="","",2965D!H37) | J52: =IF(2965D!I37="","",2965D!I37) | K52: =IF(2965D!J37="","",2965D!J37) | L52: =IF(2965D!K37="","",2965D!K37) | M52: =IF(FORMATTED!K29=TRUE(),"ü","") | N52: =IF(FORMATTED!L29=TRUE(),"ü","") | O52: =IF(2965D!N37="","",2965D!N37) | P52: =IF(2965D!P37="","",2965D!P37) | U52: =IF(2965D!Q37="","",2965D!Q37) | V52: =IF(2965D!R37="","",2965D!R37) | X52: =IF(FORMATTED!H29=TRUE(),"ü","") | Y52: =IFERROR(VLOOKUP(2965D!T37,Pilots[[SN Last 4]:[Pilot]],2,FALSE()),"") | Z52: =IF(2965D!$G$5=B52,"Max",IF(2965D!$G$5=B51,"Launches",""))
...

Sheet Instructions
A1: Start of Day
A2: 1 | B2: Save the file to Sharepoint and name it "2965D_DATE_AIRCRAFT.xlsx" e.g. 2965D_250211_ZE625.xlsx
A3: 2 | B3: Enter aircraft number and date along the top
A4: 3 | B4: Add launches and hours before flight from the F724.
A5: 4 | B5: Add the last four digits of the AC commander into the AF initials column during the in-brief.
A7: End of Day
A8: 1 | B8: Ensure the log sheet has saved to Sharepoint
A9: 2 | B9: Login to the VGS Stats Dashboard
A10: 3 | B10: Upload log sheets on the "Upload Log Sheets" page
A11: 4 | B11: Go to "Print Copy" and print the log sheet.
B13: If you really need to, the editing password for this document is "Viking"

Sheet Changelog
A1: Version | B1: Date | C1: Name | D1: Changes
A2: 1.1.0 | B2: 45027 | C2: MJ | D2: Updated SPC column to be 6 if time flown is > 9 min 30 seconds. Added CGS names into aircraft commander columns Added changelog Updated instructions with hyperlinks and next steps
A3: 1.2.0 | B3: 45030 | C3: MJ | D3: Added checkboxes to PLF columns. FORMATTED now returns TRUE or FALSE.
A4: 1.3.1 | B4: 45074 | C4: MJ | D4: Added pilots
A5: 1.4.0 | B5: 45088 | C5: CW | D5: Instruction (7) updated Extra instructions added Tickboxes added to P1 and P2 columns Duty drop down list updated Duty column headers updated on the 2965D FORMATTED table P1 and P2 columns added
A6: 1.4.1 | B6: 45101 | C6: CW | D6: Added pilot and aircraft. Various formula's updated to reflect weaknesses in new duty names and full sheets
A7: 1.4.2 | B7: 45136 | C7: MJ | D7: Fixed formula in total launches boxes using COUNTA instead of 23-COUNTBLANK. Changed duty back to G/S, AGT. Simpified instructions. Added locked cells and password-protected sheet.
A8: 2.0.0 | B8: 45112 | C8: DA | D8: Major changes to template: Added F724 entry guide Added Print Copy for if required to print log sheet
A9: 2.1.0 | B9: 45513 | C9: DA | D9: Added formatting to display max launches left
A10: 2.2.0 | B10: 45522 | C10: MJ | D10: Fixed print area on Print Copy Print copy cells no longer show 0 when the sheet is blank Fixed typo in 724 B/F cell
A11: 2.3.0 | B11: 45560 | C11: MJ | D11: Added _AIRCRAFT to capture hours and launches after flight Updated instructions with hyperlinks
A12: 2.3.1 | B12: 45564 | C12: MJ | D12: Fixed _AIRCRAFT hours and launches pulling from the wrong fields
A13: 2.3.2 | B13: 45564 | C13: MJ | D13: Fixed launches column in _AIRCRAFT pulling from the hours row
... A21: 3.3.3 | B21: 45940 | C21: MJ | D21: Added ZE557

Sheet INPUT_DATA
A1: Number | B1: Tail Letter | D1: Duty
A2: ZE528 | B2: VQ | D2: GIF
A3: ZE495 | B3: VA | D3: G/S
A4: ZE602 | B4: XB | D4: AGT
A5: ZE625 | B5: XP | D5: SCT QGI
A6: ZE527 | B6: VP | D6: SCT U/T
A7: ZE633 | B7: XX | D7: PAX
A8: ZE529 | B8: VR
A9: ZE626 | B9: XQ
A10: ZE557 | B10: WE
A15: SN Last 4 | B15: Pilot | C15: Surname
A16: 0593 | B16: DA | C16: Abbott
A17: 5744 | B17: IA | C17: Amos
A18: 9013 | B18: SA | C18: Arijs
A19: 2003 | B19: AB | C19: Baruah
A20: 2143 | B20: JB | C20: Blair
B21: SB | C21: Burton
A22: 3208 | B22: KC | C22: Carr, K
B23: CD | C23: Delaney
B24: HE | C24: Eagleson
A25: 4456 | B25: KG | C25: Gallagher
B26: SG | C26: Goddard
A27: 5909 | B27: MJ | C27: Jennings
A28: 1011 | B28: GJ | C28: Jones
A29: 796B | B29: CL | C29: Law
B30: SL | C30: Link
B31: AM | C31: Maisey
A32: 8923 | B32: AM | C32: McCormick
A33: 2006 | B33: LM | C33: McGhee
A34: 1277 | B34: JP | C34: Parker
B35: NP | C35: Patterson
A36: 6223 | B36: LP | C36: Phillips
A37: 8596 | B37: AR | C37: Ritchie
A38: 9647 | B38: PS | C38: Suggett
A39: 0103 | B39: KT | C39: Tuach
A40: 0572 | B40: CW | C40: White, C
B41: RW | C41: White, R
B42: TW | C42: Webb
B43: GW | C43: Webber

Sheet FORMATTED
A1: AircraftCommander | B1: 2ndPilot | C1: Duty | D1: TakeOffTime | E1: LandingTime | F1: FlightTime | G1: SPC | H1: PLF | I1: Aircraft | J1: Date | K1: P1 | L1: P2
A2: =2965D!B10 -> Jennings | B2: =2965D!C10 -> Smith | C2: =2965D!D10 -> GIF | D2: =2965D!E10+Formatted[[#This Row],[Date]] -> 46067.458 | E2: =2965D!F10+Formatted[[#This Row],[Date]] -> 46067.464 | F2: =ROUND((Formatted[[#This Row],[LandingTime]]-Formatted[[#This Row],[TakeOffTime]]) * 1440, 0) -> 8 | G2: =2965D!O10 -> 6 | H2: =FALSE() -> 0 | I2: =2965D!$F$2 -> ZE633 | J2: =2965D!$O$2 -> 46067 | K2: =FALSE() -> FALSE | L2: =FALSE() -> FALSE
A3: =2965D!B11 -> Jennings | B3: =2965D!C11 -> Smith | C3: =2965D!D11 -> GIF | D3: =2965D!E11+Formatted[[#This Row],[Date]] -> 46067.469 | E3: =2965D!F11+Formatted[[#This Row],[Date]] -> 46067.473 | F3: =ROUND((Formatted[[#This Row],[LandingTime]]-Formatted[[#This Row],[TakeOffTime]]) * 1440, 0) -> 5 | G3: =2965D!O11 -> 1 | H3: =FALSE() -> 0 | I3: =2965D!$F$2 -> ZE633 | J3: =2965D!$O$2 -> 46067 | K3: =FALSE() -> FALSE | L3: =FALSE() -> FALSE
A4: =2965D!B12 -> Jennings | B4: =2965D!C12 -> Derp | C4: =2965D!D12 -> GIF | D4: =2965D!E12+Formatted[[#This Row],[Date]] -> 46067.478 | E4: =2965D!F12+Formatted[[#This Row],[Date]] -> 46067.481 | F4: =ROUND((Formatted[[#This Row],[LandingTime]]-Formatted[[#This Row],[TakeOffTime]]) * 1440, 0) -> 5 | G4: =2965D!O12 -> 1 | H4: =FALSE() -> 0 | I4: =2965D!$F$2 -> ZE633 | J4: =2965D!$O$2 -> 46067 | K4: =FALSE() -> FALSE | L4: =FALSE() -> FALSE
A5: =2965D!B13 -> Jennings | B5: =2965D!C13 -> Derp | C5: =2965D!D13 -> GIF | D5: =2965D!E13+Formatted[[#This Row],[Date]] -> 46067.486 | E5: =2965D!F13+Formatted[[#This Row],[Date]] -> 46067.489 | F5: =ROUND((Formatted[[#This Row],[LandingTime]]-Formatted[[#This Row],[TakeOffTime]]) * 1440, 0) -> 4 | G5: =2965D!O13 -> 1 | H5: =FALSE() -> 0 | I5: =2965D!$F$2 -> ZE633 | J5: =2965D!$O$2 -> 46067 | K5: =FALSE() -> FALSE | L5: =FALSE() -> FALSE
A6: =2965D!B14 -> Jennings | B6: =2965D!C14 -> Bojangles | C6: =2965D!D14 -> GIF | D6: =2965D!E14+Formatted[[#This Row],[Date]] -> 46067.494 | E6: =2965D!F14+Formatted[[#This Row],[Date]] -> 46067.499 | F6: =ROUND((Formatted[[#This Row],[LandingTime]]-Formatted[[#This Row],[TakeOffTime]]) * 1440, 0) -> 6 | G6: =2965D!O14 -> 7 | H6: =FALSE() -> 0 | I6: =2965D!$F$2 -> ZE633 | J6: =2965D!$O$2 -> 46067 | K6: =FALSE() -> FALSE | L6: =FALSE() -> FALSE
A7: =2965D!B15 -> Jennings | B7: =2965D!C15 -> Bojangles | C7: =2965D!D15 -> GIF | D7: =2965D!E15+Formatted[[#This Row],[Date]] -> 46067.503 | E7: =2965D!F15+Formatted[[#This Row],[Date]] -> 46067.506 | F7: =ROUND((Formatted[[#This Row],[LandingTime]]-Formatted[[#This Row],[TakeOffTime]]) * 1440, 0) -> 4 | G7: =2965D!O15 -> 1 | H7: TRUE | I7: =2965D!$F$2 -> ZE633 | J7: =2965D!$O$2 -> 46067 | K7: =FALSE() -> FALSE | L7: =FALSE() -> FALSE
A8: =2965D!B16 -> Jennings | B8: =2965D!C16 -> Bloggs | C8: =2965D!D16 -> AGT | D8: =2965D!E16+Formatted[[#This Row],[Date]] -> 46067.626 | E8: =2965D!F16+Formatted[[#This Row],[Date]] -> 46067.629 | F8: =ROUND((Formatted[[#This Row],[LandingTime]]-Formatted[[#This Row],[TakeOffTime]]) * 1440, 0) -> 4 | G8: =2965D!O16 -> 1 | H8: =FALSE() -> 0 | I8: =2965D!$F$2 -> ZE633 | J8: =2965D!$O$2 -> 46067 | K8: =FALSE() -> FALSE | L8: =FALSE() -> FALSE
A9: =2965D!B17 -> Jennings | B9: =2965D!C17 -> Bloggs | C9: =2965D!D17 -> AGT | D9: =2965D!E17+Formatted[[#This Row],[Date]] -> 46067.636 | E9: =2965D!F17+Formatted[[#This Row],[Date]] -> 46067.64 | F9: =ROUND((Formatted[[#This Row],[LandingTime]]-Formatted[[#This Row],[TakeOffTime]]) * 1440, 0) -> 5 | G9: =2965D!O17 -> 1 | H9: =FALSE() -> 0 | I9: =2965D!$F$2 -> ZE633 | J9: =2965D!$O$2 -> 46067 | K9: =FALSE() -> FALSE | L9: =FALSE() -> FALSE
A10: =2965D!B18 -> Jennings | B10: =2965D!C18 -> Bloggs | C10: =2965D!D18 -> AGT | D10: =2965D!E18+Formatted[[#This Row],[Date]] -> 46067.645 | E10: =2965D!F18+Formatted[[#This Row],[Date]] -> 46067.649 | F10: =ROUND((Formatted[[#This Row],[LandingTime]]-Formatted[[#This Row],[TakeOffTime]]) * 1440, 0) -> 5 | G10: =2965D!O18 -> 1 | H10: =FALSE() -> 0 | I10: =2965D!$F$2 -> ZE633 | J10: =2965D!$O$2 -> 46067 | K10: =FALSE() -> FALSE | L10: =FALSE() -> FALSE
A11: =2965D!B19 -> Jennings | B11: =2965D!C19 -> Bloggs | C11: =2965D!D19 -> AGT | D11: =2965D!E19+Formatted[[#This Row],[Date]] -> 46067.656 | E11: =2965D!F19+Formatted[[#This Row],[Date]] -> 46067.66 | F11: =ROUND((Formatted[[#This Row],[LandingTime]]-Formatted[[#This Row],[TakeOffTime]]) * 1440, 0) -> 5 | G11: =2965D!O19 -> 1 | H11: =FALSE() -> 0 | I11: =2965D!$F$2 -> ZE633 | J11: =2965D!$O$2 -> 46067 | K11: =FALSE() -> FALSE | L11: =FALSE() -> FALSE
A12: =2965D!B20 -> Abbott | B12: =2965D!C20 -> Bloggs | C12: =2965D!D20 -> SCT QGI | D12: =2965D!E20+Formatted[[#This Row],[Date]] -> 46067.669 | E12: =2965D!F20+Formatted[[#This Row],[Date]] -> 46067.672 | F12: =ROUND((Formatted[[#This Row],[LandingTime]]-Formatted[[#This Row],[TakeOffTime]]) * 1440, 0) -> 5 | G12: =2965D!O20 -> 1 | H12: =FALSE() -> 0 | I12: =2965D!$F$2 -> ZE633 | J12: =2965D!$O$2 -> 46067 | K12: TRUE | L12: FALSE
A13: =2965D!B21 -> Abbott | B13: =2965D!C21 -> Bloggs | C13: =2965D!D21 -> SCT U/T | D13: =2965D!E21+Formatted[[#This Row],[Date]] -> 46067.681 | E13: =2965D!F21+Formatted[[#This Row],[Date]] -> 46067.684 | F13: =ROUND((Formatted[[#This Row],[LandingTime]]-Formatted[[#This Row],[TakeOffTime]]) * 1440, 0) -> 5 | G13: =2965D!O21 -> 1 | H13: =FALSE() -> 0 | I13: =2965D!$F$2 -> ZE633 | J13: =2965D!$O$2 -> 46067 | K13: =FALSE() -> FALSE | L13: TRUE
A14: =2965D!B22 -> Abbott | B14: =2965D!C22 -> Bloggs | C14: =2965D!D22 -> PAX | D14: =2965D!E22+Formatted[[#This Row],[Date]] -> 46067.69 | E14: =2965D!F22+Formatted[[#This Row],[Date]] -> 46067.693 | F14: =ROUND((Formatted[[#This Row],[LandingTime]]-Formatted[[#This Row],[TakeOffTime]]) * 1440, 0) -> 4 | G14: =2965D!O22 -> 1 | H14: =FALSE() -> 0 | I14: =2965D!$F$2 -> ZE633 | J14: =2965D!$O$2 -> 46067 | K14: =FALSE() -> FALSE | L14: =FALSE() -> FALSE
A15: =2965D!B23 -> 0 | B15: =2965D!C23 -> 0 | C15: =2965D!D23 -> 0 | D15: =2965D!E23+Formatted[[#This Row],[Date]] -> 46067 | E15: =2965D!F23+Formatted[[#This Row],[Date]] -> 46067 | F15: =ROUND((Formatted[[#This Row],[LandingTime]]-Formatted[[#This Row],[TakeOffTime]]) * 1440, 0) -> 0 | G15: =2965D!O23 | H15: =FALSE() -> 0 | I15: =2965D!$F$2 -> ZE633 | J15: =2965D!$O$2 -> 46067 | K15: =FALSE() -> FALSE | L15: =FALSE() -> FALSE
A16: =2965D!B24 -> 0 | B16: =2965D!C24 -> 0 | C16: =2965D!D24 -> 0 | D16: =2965D!E24+Formatted[[#This Row],[Date]] -> 46067 | E16: =2965D!F24+Formatted[[#This Row],[Date]] -> 46067 | F16: =ROUND((Formatted[[#This Row],[LandingTime]]-Formatted[[#This Row],[TakeOffTime]]) * 1440, 0) -> 0 | G16: =2965D!O24 | H16: =FALSE() -> 0 | I16: =2965D!$F$2 -> ZE633 | J16: =2965D!$O$2 -> 46067 | K16: =FALSE() -> FALSE | L16: =FALSE() -> FALSE
A17: =2965D!B25 -> 0 | B17: =2965D!C25 -> 0 | C17: =2965D!D25 -> 0 | D17: =2965D!E25+Formatted[[#This Row],[Date]] -> 46067 | E17: =2965D!F25+Formatted[[#This Row],[Date]] -> 46067 | F17: =ROUND((Formatted[[#This Row],[LandingTime]]-Formatted[[#This Row],[TakeOffTime]]) * 1440, 0) -> 0 | G17: =2965D!O25 | H17: =FALSE() -> 0 | I17: =2965D!$F$2 -> ZE633 | J17: =2965D!$O$2 -> 46067 | K17: =FALSE() -> FALSE | L17: =FALSE() -> FALSE
A18: =2965D!B26 -> 0 | B18: =2965D!C26 -> 0 | C18: =2965D!D26 -> 0 | D18: =2965D!E26+Formatted[[#This Row],[Date]] -> 46067 | E18: =2965D!F26+Formatted[[#This Row],[Date]] -> 46067 | F18: =ROUND((Formatted[[#This Row],[LandingTime]]-Formatted[[#This Row],[TakeOffTime]]) * 1440, 0) -> 0 | G18: =2965D!O26 | H18: =FALSE() -> 0 | I18: =2965D!$F$2 -> ZE633 | J18: =2965D!$O$2 -> 46067 | K18: =FALSE() -> FALSE | L18: =FALSE() -> FALSE
A19: =2965D!B27 -> 0 | B19: =2965D!C27 -> 0 | C19: =2965D!D27 -> 0 | D19: =2965D!E27+Formatted[[#This Row],[Date]] -> 46067 | E19: =2965D!F27+Formatted[[#This Row],[Date]] -> 46067 | F19: =ROUND((Formatted[[#This Row],[LandingTime]]-Formatted[[#This Row],[TakeOffTime]]) * 1440, 0) -> 0 | G19: =2965D!O27 | H19: =FALSE() -> 0 | I19: =2965D!$F$2 -> ZE633 | J19: =2965D!$O$2 -> 46067 | K19: =FALSE() -> FALSE | L19: =FALSE() -> FALSE
A20: =2965D!B28 -> 0 | B20: =2965D!C28 -> 0 | C20: =2965D!D28 -> 0 | D20: =2965D!E28+Formatted[[#This Row],[Date]] -> 46067 | E20: =2965D!F28+Formatted[[#This Row],[Date]] -> 46067 | F20: =ROUND((Formatted[[#This Row],[LandingTime]]-Formatted[[#This Row],[TakeOffTime]]) * 1440, 0) -> 0 | G20: =2965D!O28 | H20: =FALSE() -> 0 | I20: =2965D!$F$2 -> ZE633 | J20: =2965D!$O$2 -> 46067 | K20: =FALSE() -> FALSE | L20: =FALSE() -> FALSE
A21: =2965D!B29 -> 0 | B21: =2965D!C29 -> 0 | C21: =2965D!D29 -> 0 | D21: =2965D!E29+Formatted[[#This Row],[Date]] -> 46067 | E21: =2965D!F29+Formatted[[#This Row],[Date]] -> 46067 | F21: =ROUND((Formatted[[#This Row],[LandingTime]]-Formatted[[#This Row],[TakeOffTime]]) * 1440, 0) -> 0 | G21: =2965D!O29 | H21: =FALSE() -> 0 | I21: =2965D!$F$2 -> ZE633 | J21: =2965D!$O$2 -> 46067 | K21: =FALSE() -> FALSE | L21: =FALSE() -> FALSE
A22: =2965D!B30 -> 0 | B22: =2965D!C30 -> 0 | C22: =2965D!D30 -> 0 | D22: =2965D!E30+Formatted[[#This Row],[Date]] -> 46067 | E22: =2965D!F30+Formatted[[#This Row],[Date]] -> 46067 | F22: =ROUND((Formatted[[#This Row],[LandingTime]]-Formatted[[#This Row],[TakeOffTime]]) * 1440, 0) -> 0 | G22: =2965D!O30 | H22: =FALSE() -> 0 | I22: =2965D!$F$2 -> ZE633 | J22: =2965D!$O$2 -> 46067 | K22: =FALSE() -> FALSE | L22: =FALSE() -> FALSE
A23: =2965D!B31 -> 0 | B23: =2965D!C31 -> 0 | C23: =2965D!D31 -> 0 | D23: =2965D!E31+Formatted[[#This Row],[Date]] -> 46067 | E23: =2965D!F31+Formatted[[#This Row],[Date]] -> 46067 | F23: =ROUND((Formatted[[#This Row],[LandingTime]]-Formatted[[#This Row],[TakeOffTime]]) * 1440, 0) -> 0 | G23: =2965D!O31 | H23: =FALSE() -> 0 | I23: =2965D!$F$2 -> ZE633 | J23: =2965D!$O$2 -> 46067 | K23: =FALSE() -> FALSE | L23: =FALSE() -> FALSE
A24: =2965D!B32 -> 0 | B24: =2965D!C32 -> 0 | C24: =2965D!D32 -> 0 | D24: =2965D!E32+Formatted[[#This Row],[Date]] -> 46067 | E24: =2965D!F32+Formatted[[#This Row],[Date]] -> 46067 | F24: =ROUND((Formatted[[#This Row],[LandingTime]]-Formatted[[#This Row],[TakeOffTime]]) * 1440, 0) -> 0 | G24: =2965D!O32 | H24: =FALSE() -> 0 | I24: =2965D!$F$2 -> ZE633 | J24: =2965D!$O$2 -> 46067 | K24: =FALSE() -> FALSE | L24: =FALSE() -> FALSE
A25: =2965D!B33 -> 0 | B25: =2965D!C33 -> 0 | C25: =2965D!D33 -> 0 | D25: =2965D!E33+Formatted[[#This Row],[Date]] -> 46067 | E25: =2965D!F33+Formatted[[#This Row],[Date]] -> 46067 | F25: =ROUND((Formatted[[#This Row],[LandingTime]]-Formatted[[#This Row],[TakeOffTime]]) * 1440, 0) -> 0 | G25: =2965D!O33 | H25: =FALSE() -> 0 | I25: =2965D!$F$2 -> ZE633 | J25: =2965D!$O$2 -> 46067 | K25: =FALSE() -> FALSE | L25: =FALSE() -> FALSE
... A33: =2965D!B41 -> 0 | B33: =2965D!C41 -> 0 | C33: =2965D!D41 -> 0 | D33: =2965D!E41+Formatted[[#This Row],[Date]] -> 46067 | E33: =2965D!F41+Formatted[[#This Row],[Date]] -> 46067 | F33: =ROUND((Formatted[[#This Row],[LandingTime]]-Formatted[[#This Row],[TakeOffTime]]) * 1440, 0) -> 0 | G33: =2965D!O41 | H33: =FALSE() -> 0 | I33: =2965D!$F$2 -> ZE633 | J33: =2965D!$O$2 -> 46067 | K33: =FALSE() -> FALSE | L33: =FALSE() -> FALSE

Sheet _AIRCRAFT
A1: Date | B1: Aircraft | C1: Hours After | D1: Launches After
A2: =2965D!O2 -> 46067 | B2: =2965D!F2 -> ZE633 | C2: =2965D!C4+SUM(2965D!P42:R42) -> 119.95278 | D2: =2965D!C5+SUM(2965D!P43:R43) -> 22516
