Workbook
Name AircraftList: Aircraft[Number]
Name DutyList: Duty[Duty]
Name PilotList: Pilots[Surname]
Name SPCList: Table4[SPC Codes]

Sheet 2965B
C2: 661 VGS | D2: A/C Number | H2: A/C Tail Letters | L2: =IF($F2="","",IFERROR(VLOOKUP(F2,Aircraft[#All],2,FALSE),"Not listed")) -> VA | N2: Date
B4: F724 Hours B/F
B5: F724 Launches B/F | E5: Launches Left (If 30 or less)
A7: Ser No. | G7: Trainee | J7: SCT | L7: Claimed By | N7: Other (G) | O7: SPC | P7: PLF | Q7: After Flight Initials
G8: GIF | H8: G/S | I8: AGT | J8: QGI | K8: U/T | O8: 1- Winch Launch (Circuit) 2- Aerotow Only 3- Aerotow + Soaring 4- Aerotow + Stalling 5- Aerotow + Aeros 6- Winch Launch + Soaring 7- Winch Launch + Aeros 8- Maintenance Flight Test
B9: Aircraft Commander | C9: 2nd Pilot/Trainee or Passenger | D9: Duty | E9: Take Off Time | F9: Landing Time | G9: (B) | H9: (C) | I9: (D) | J9: (E) | K9: (F) | L9: P1 | M9: P2 | R9: Warnings | S9: SPC Found | T9: Time
A10: 1 | G10: =IF($D10="","",IF($D10=G$8,$F10-$E10,"")) -> 0.0034722222 | H10: =IF($D10="","",IF($D10=H$8,$F10-$E10,"")) | I10: =IF($D10="","",IF($D10=I$8,$F10-$E10,"")) | J10: =IF($D10="","",IF($D10=CONCATENATE(J$7," ",J$8),$F10-$E10,"")) | K10: =IF($D10="","",IF($D10=CONCATENATE(J$7," ",K$8),$F10-$E10,"")) | L10: FALSE | M10: FALSE | N10: =IF($D10="","",IF($D10="PAX",$F10-$E10,"")) | O10: =IF(COUNTA($B10:$F10)=0,"","1 - Winch Launch (Circuit)") | P10: FALSE | R10: =IF($G$5=A10,"Max Launches","") | S10: =IF(O10="","",TRIM(LEFT(O10,1))*1) -> 1 | T10: =SUM(G10,H10,I10,J10,K10,N10) -> 0.0034722222
A11: 2 | G11: =IF($D11="","",IF($D11=G$8,$F11-$E11,"")) -> 0.0034722222 | H11: =IF($D11="","",IF($D11=H$8,$F11-$E11,"")) | I11: =IF($D11="","",IF($D11=I$8,$F11-$E11,"")) | J11: =IF($D11="","",IF($D11=CONCATENATE(J$7," ",J$8),$F11-$E11,"")) | K11: =IF($D11="","",IF($D11=CONCATENATE(J$7," ",K$8),$F11-$E11,"")) | L11: FALSE | M11: FALSE | N11: =IF($D11="","",IF($D11="PAX",$F11-$E11,"")) | O11: =IF(COUNTA($B11:$F11)=0,"","1 - Winch Launch (Circuit)") | P11: FALSE | R11: =IF($G$5=A11,"Max Launches","") | S11: =IF(O11="","",TRIM(LEFT(O11,1))*1) -> 1 | T11: =SUM(G11,H11,I11,J11,K11,N11) -> 0.0034722222
A12: 3 | G12: =IF($D12="","",IF($D12=G$8,$F12-$E12,"")) | H12: =IF($D12="","",IF($D12=H$8,$F12-$E12,"")) | I12: =IF($D12="","",IF($D12=I$8,$F12-$E12,"")) | J12: =IF($D12="","",IF($D12=CONCATENATE(J$7," ",J$8),$F12-$E12,"")) -> 0.017361111 | K12: =IF($D12="","",IF($D12=CONCATENATE(J$7," ",K$8),$F12-$E12,"")) | L12: FALSE | M12: FALSE | N12: =IF($D12="","",IF($D12="PAX",$F12-$E12,"")) | O12: =IF(COUNTA($B12:$F12)=0,"","1 - Winch Launch (Circuit)") | P12: FALSE | R12: =IF($G$5=A12,"Max Launches","") | S12: =IF(O12="","",TRIM(LEFT(O12,1))*1) -> 6 | T12: =SUM(G12,H12,I12,J12,K12,N12) -> 0.017361111
A13: 4 | G13: =IF($D13="","",IF($D13=G$8,$F13-$E13,"")) | H13: =IF($D13="","",IF($D13=H$8,$F13-$E13,"")) | I13: =IF($D13="","",IF($D13=I$8,$F13-$E13,"")) | J13: =IF($D13="","",IF($D13=CONCATENATE(J$7," ",J$8),$F13-$E13,"")) -> 0.00069444444 | K13: =IF($D13="","",IF($D13=CONCATENATE(J$7," ",K$8),$F13-$E13,"")) | L13: FALSE | M13: FALSE | N13: =IF($D13="","",IF($D13="PAX",$F13-$E13,"")) | O13: =IF(COUNTA($B13:$F13)=0,"","1 - Winch Launch (Circuit)") | P13: FALSE | R13: =IF($G$5=A13,"Max Launches","") | S13: =IF(O13="","",TRIM(LEFT(O13,1))*1) -> 1 | T13: =SUM(G13,H13,I13,J13,K13,N13) -> 0.00069444444
A14: 5 | G14: =IF($D14="","",IF($D14=G$8,$F14-$E14,"")) | H14: =IF($D14="","",IF($D14=H$8,$F14-$E14,"")) | I14: =IF($D14="","",IF($D14=I$8,$F14-$E14,"")) | J14: =IF($D14="","",IF($D14=CONCATENATE(J$7," ",J$8),$F14-$E14,"")) | K14: =IF($D14="","",IF($D14=CONCATENATE(J$7," ",K$8),$F14-$E14,"")) | L14: FALSE | M14: FALSE | N14: =IF($D14="","",IF($D14="PAX",$F14-$E14,"")) -> 0.0034722222 | O14: =IF(COUNTA($B14:$F14)=0,"","1 - Winch Launch (Circuit)") | P14: FALSE | R14: =IF($G$5=A14,"Max Launches","") | S14: =IF(O14="","",TRIM(LEFT(O14,1))*1) -> 1 | T14: =SUM(G14,H14,I14,J14,K14,N14) -> 0.0034722222
A15: 6 | G15: =IF($D15="","",IF($D15=G$8,$F15-$E15,"")) | H15: =IF($D15="","",IF($D15=H$8,$F15-$E15,"")) | I15: =IF($D15="","",IF($D15=I$8,$F15-$E15,"")) | J15: =IF($D15="","",IF($D15=CONCATENATE(J$7," ",J$8),$F15-$E15,"")) | K15: =IF($D15="","",IF($D15=CONCATENATE(J$7," ",K$8),$F15-$E15,"")) | L15: FALSE | M15: FALSE | N15: =IF($D15="","",IF($D15="PAX",$F15-$E15,"")) | O15: =IF(COUNTA($B15:$F15)=0,"","1 - Winch Launch (Circuit)") | P15: FALSE | R15: =IF($G$5=A15,"Max Launches","") | S15: =IF(O15="","",TRIM(LEFT(O15,1))*1) | T15: =SUM(G15,H15,I15,J15,K15,N15) -> 0
A16: 7 | G16: =IF($D16="","",IF($D16=G$8,$F16-$E16,"")) | H16: =IF($D16="","",IF($D16=H$8,$F16-$E16,"")) | I16: =IF($D16="","",IF($D16=I$8,$F16-$E16,"")) | J16: =IF($D16="","",IF($D16=CONCATENATE(J$7," ",J$8),$F16-$E16,"")) | K16: =IF($D16="","",IF($D16=CONCATENATE(J$7," ",K$8),$F16-$E16,"")) | L16: FALSE | M16: FALSE | N16: =IF($D16="","",IF($D16="PAX",$F16-$E16,"")) | O16: =IF(COUNTA($B16:$F16)=0,"","1 - Winch Launch (Circuit)") | P16: FALSE | R16: =IF($G$5=A16,"Max Launches","") | S16: =IF(O16="","",TRIM(LEFT(O16,1))*1) | T16: =SUM(G16,H16,I16,J16,K16,N16) -> 0
A17: 8 | G17: =IF($D17="","",IF($D17=G$8,$F17-$E17,"")) | H17: =IF($D17="","",IF($D17=H$8,$F17-$E17,"")) | I17: =IF($D17="","",IF($D17=I$8,$F17-$E17,"")) | J17: =IF($D17="","",IF($D17=CONCATENATE(J$7," ",J$8),$F17-$E17,"")) | K17: =IF($D17="","",IF($D17=CONCATENATE(J$7," ",K$8),$F17-$E17,"")) | L17: FALSE | M17: FALSE | N17: =IF($D17="","",IF($D17="PAX",$F17-$E17,"")) | O17: =IF(COUNTA($B17:$F17)=0,"","1 - Winch Launch (Circuit)") | P17: FALSE | R17: =IF($G$5=A17,"Max Launches","") | S17: =IF(O17="","",TRIM(LEFT(O17,1))*1) | T17: =SUM(G17,H17,I17,J17,K17,N17) -> 0
A18: 9 | G18: =IF($D18="","",IF($D18=G$8,$F18-$E18,"")) | H18: =IF($D18="","",IF($D18=H$8,$F18-$E18,"")) | I18: =IF($D18="","",IF($D18=I$8,$F18-$E18,"")) | J18: =IF($D18="","",IF($D18=CONCATENATE(J$7," ",J$8),$F18-$E18,"")) | K18: =IF($D18="","",IF($D18=CONCATENATE(J$7," ",K$8),$F18-$E18,"")) | L18: FALSE | M18: FALSE | N18: =IF($D18="","",IF($D18="PAX",$F18-$E18,"")) | O18: =IF(COUNTA($B18:$F18)=0,"","1 - Winch Launch (Circuit)") | P18: FALSE | R18: =IF($G$5=A18,"Max Launches","") | S18: =IF(O18="","",TRIM(LEFT(O18,1))*1) | T18: =SUM(G18,H18,I18,J18,K18,N18) -> 0
A19: 10 | G19: =IF($D19="","",IF($D19=G$8,$F19-$E19,"")) | H19: =IF($D19="","",IF($D19=H$8,$F19-$E19,"")) | I19: =IF($D19="","",IF($D19=I$8,$F19-$E19,"")) | J19: =IF($D19="","",IF($D19=CONCATENATE(J$7," ",J$8),$F19-$E19,"")) | K19: =IF($D19="","",IF($D19=CONCATENATE(J$7," ",K$8),$F19-$E19,"")) | L19: FALSE | M19: FALSE | N19: =IF($D19="","",IF($D19="PAX",$F19-$E19,"")) | O19: =IF(COUNTA($B19:$F19)=0,"","1 - Winch Launch (Circuit)") | P19: FALSE | R19: =IF($G$5=A19,"Max Launches","") | S19: =IF(O19="","",TRIM(LEFT(O19,1))*1) | T19: =SUM(G19,H19,I19,J19,K19,N19) -> 0
A20: 11 | G20: =IF($D20="","",IF($D20=G$8,$F20-$E20,"")) | H20: =IF($D20="","",IF($D20=H$8,$F20-$E20,"")) | I20: =IF($D20="","",IF($D20=I$8,$F20-$E20,"")) | J20: =IF($D20="","",IF($D20=CONCATENATE(J$7," ",J$8),$F20-$E20,"")) | K20: =IF($D20="","",IF($D20=CONCATENATE(J$7," ",K$8),$F20-$E20,"")) | L20: FALSE | M20: FALSE | N20: =IF($D20="","",IF($D20="PAX",$F20-$E20,"")) | O20: =IF(COUNTA($B20:$F20)=0,"","1 - Winch Launch (Circuit)") | P20: FALSE | R20: =IF($G$5=A20,"Max Launches","") | S20: =IF(O20="","",TRIM(LEFT(O20,1))*1) | T20: =SUM(G20,H20,I20,J20,K20,N20) -> 0
A21: 12 | G21: =IF($D21="","",IF($D21=G$8,$F21-$E21,"")) | H21: =IF($D21="","",IF($D21=H$8,$F21-$E21,"")) | I21: =IF($D21="","",IF($D21=I$8,$F21-$E21,"")) | J21: =IF($D21="","",IF($D21=CONCATENATE(J$7," ",J$8),$F21-$E21,"")) | K21: =IF($D21="","",IF($D21=CONCATENATE(J$7," ",K$8),$F21-$E21,"")) | L21: FALSE | M21: FALSE | N21: =IF($D21="","",IF($D21="PAX",$F21-$E21,"")) | O21: =IF(COUNTA($B21:$F21)=0,"","1 - Winch Launch (Circuit)") | P21: FALSE | R21: =IF($G$5=A21,"Max Launches","") | S21: =IF(O21="","",TRIM(LEFT(O21,1))*1) | T21: =SUM(G21,H21,I21,J21,K21,N21) -> 0
... A39: 30 | G39: =IF($D39="","",IF($D39=G$8,$F39-$E39,"")) | H39: =IF($D39="","",IF($D39=H$8,$F39-$E39,"")) | I39: =IF($D39="","",IF($D39=I$8,$F39-$E39,"")) | J39: =IF($D39="","",IF($D39=CONCATENATE(J$7," ",J$8),$F39-$E39,"")) | K39: =IF($D39="","",IF($D39=CONCATENATE(J$7," ",K$8),$F39-$E39,"")) | L39: FALSE | M39: FALSE | N39: =IF($D39="","",IF($D39="PAX",$F39-$E39,"")) | O39: =IF(COUNTA($B39:$F39)=0,"","1 - Winch Launch (Circuit)") | P39: FALSE | R39: =IF($G$5=A39,"Max Launches","") | S39: =IF(O39="","",TRIM(LEFT(O39,1))*1) | T39: =SUM(G39,H39,I39,J39,K39,N39) -> 0
E40: Total Hours | G40: =IF(SUM(G10:G39)=0,"",SUM(G10:G39)) -> 0.0069444444 | H40: =IF(SUM(H10:H39)=0,"",SUM(H10:H39)) | I40: =IF(SUM(I10:I39)=0,"",SUM(I10:I39)) | J40: =IF(SUM(J10:J39)=0,"",SUM(J10:J39)) -> 0.018055556 | K40: =IF(SUM(K10:K39)=0,"",SUM(K10:K39)) | N40: =IF(SUM(N10:N39)=0,"",SUM(N10:N39)) -> 0.0034722222
E41: Total Launches | G41: =IF(COUNT(G10:G39)=0,"",COUNT(G10:G39)) -> 2 | H41: =IF(COUNT(H10:H39)=0,"",COUNT(H10:H39)) | I41: =IF(COUNT(I10:I39)=0,"",COUNT(I10:I39)) | J41: =IF(COUNT(J10:J39)=0,"",COUNT(J10:J39)) -> 2 | K41: =IF(COUNT(K10:K39)=0,"",COUNT(K10:K39)) | N41: =IF(COUNT(N10:N39)=0,"",COUNT(N10:N39)) -> 1
G43: 1 | H43: 2 | I43: 3 | J43: 4 | K43: 5 | L43: 6 | M43: 7 | N43: 8
F44: Hours Totals | G44: =SUMIF($S$10:$S$39,1,$T$10:$T$39) -> 0.011111111 | H44: =SUMIF($S$10:$S$39,2,$T$10:$T$39) -> 0 | I44: =SUMIF($S$10:$S$39,3,$T$10:$T$39) -> 0 | J44: =SUMIF($S$10:$S$39,4,$T$10:$T$39) -> 0 | K44: =SUMIF($S$10:$S$39,5,$T$10:$T$39) -> 0 | L44: =SUMIF($S$10:$S$39,6,$T$10:$T$39) -> 0.017361111 | M44: =SUMIF($S$10:$S$39,7,$T$10:$T$39) -> 0 | N44: =SUMIF($S$10:$S$39,8,$T$10:$T$39) -> 0
F45: Lchs | G45: =COUNTIF($S$10:$S$39,1) -> 4 | H45: =COUNTIF($S$10:$S$39,2) -> 0 | I45: =COUNTIF($S$10:$S$39,3) -> 0 | J45: =COUNTIF($S$10:$S$39,4) -> 0 | K45: =COUNTIF($S$10:$S$39,5) -> 0 | L45: =COUNTIF($S$10:$S$39,6) -> 1 | M45: =COUNTIF($S$10:$S$39,7) -> 0 | N45: =COUNTIF($S$10:$S$39,8) -> 0

Sheet Print Copy
B2: RAF Glider Flying Times | E2: Unit: | F2: 661 VGS | H2: Date: | I2: ='2965B'!O2 -> 46275 | L2: A/C Number: | O2: ='2965B'!F2 -> ZE495 | R2: A/C Tail Letters: | V2: ='2965B'!L2 -> VA | X2: RAF Form 2965B (Revised 8/26)
B4: ACTION AFTER FLIGHT HAS COMMENCED - TO BE COMPLETED IAW 2 FTS DUTY HOLDER ORDERS (DHOs) 2401(5)
B5: Serial No of Flight | C5: (Individuals with the same surname should have their forename initial added after their surname) | F5: Duty (GIF, GS, AGT, SCT, JSAT, PAX etc) | G5: Time of Take-Off | H5: Time of Landing | I5: Trainee (Hours:Min) | L5: Other Flying (Hours:Min) | M5: SCT | Q5: Sortie Profile Codes (SPC) (Aircraft Commander to complete) (Hours:Min) | Y5: Aerotow (ü) | Z5: PLF (ü) | AA5: After Flight Initials
M6: (Hours:Min) | O6: Claimed By (ü)
C7: Surname of Aircraft Commander | D7: Surname of Second Pilot, Trainee or PAX | I7: GIF | J7: G/S | K7: AGT | M7: U/T | N7: QGI | O7: P1 | P7: P2 | Q7: 1 | R7: 2 | S7: 3 | T7: 4 | U7: 5 | V7: 6 | W7: 7 | X7: 8
B8: 1 | C8: ='2965B'!B10 -> Jarrold | D8: ='2965B'!C10 -> Bloggs | F8: ='2965B'!D10 -> GIF | G8: ='2965B'!E10 -> 0.375 | H8: ='2965B'!F10 -> 0.37847222 | I8: ='2965B'!G10 -> 0.0034722222 | J8: ='2965B'!H10 | K8: ='2965B'!I10 | L8: ='2965B'!N10 | M8: ='2965B'!K10 | N8: ='2965B'!J10 | O8: =IF('2965B'!L10=TRUE,"ü","") | P8: =IF('2965B'!M10=TRUE,"ü","") | Q8: =IF('2965B'!S10=1,'2965B'!T10,"") -> 0.0034722222 | R8: =IF('2965B'!S10=2,'2965B'!T10,"") | S8: =IF('2965B'!S10=3,'2965B'!T10,"") | T8: =IF('2965B'!S10=4,'2965B'!T10,"") | U8: =IF('2965B'!S10=5,'2965B'!T10,"") | V8: =IF('2965B'!S10=6,'2965B'!T10,"") | W8: =IF('2965B'!S10=7,'2965B'!T10,"") | X8: =IF('2965B'!S10=8,'2965B'!T10,"") | Y8: =IF(OR('2965B'!S10=2,'2965B'!S10=3,'2965B'!S10=4,'2965B'!S10=5),"ü","") | Z8: =IF('2965B'!P10=TRUE,"ü","") | AA8: =IFERROR(VLOOKUP('2965B'!Q10,Pilots[[SN Last 3]:[Pilot]],2,FALSE),"") -> MJ | AB8: =IF('2965B'!$G$5=B8,"Max","")
B9: 2 | C9: ='2965B'!B11 -> Winslow, C | D9: ='2965B'!C11 -> Joe | F9: ='2965B'!D11 -> GIF | G9: ='2965B'!E11 -> 0.38194444 | H9: ='2965B'!F11 -> 0.38541667 | I9: ='2965B'!G11 -> 0.0034722222 | J9: ='2965B'!H11 | K9: ='2965B'!I11 | L9: ='2965B'!N11 | M9: ='2965B'!K11 | N9: ='2965B'!J11 | O9: =IF('2965B'!L11=TRUE,"ü","") | P9: =IF('2965B'!M11=TRUE,"ü","") | Q9: =IF('2965B'!S11=1,'2965B'!T11,"") -> 0.0034722222 | R9: =IF('2965B'!S11=2,'2965B'!T11,"") | S9: =IF('2965B'!S11=3,'2965B'!T11,"") | T9: =IF('2965B'!S11=4,'2965B'!T11,"") | U9: =IF('2965B'!S11=5,'2965B'!T11,"") | V9: =IF('2965B'!S11=6,'2965B'!T11,"") | W9: =IF('2965B'!S11=7,'2965B'!T11,"") | X9: =IF('2965B'!S11=8,'2965B'!T11,"") | Y9: =IF(OR('2965B'!S11=2,'2965B'!S11=3,'2965B'!S11=4,'2965B'!S11=5),"ü","") | Z9: =IF('2965B'!P11=TRUE,"ü","") | AA9: =IFERROR(VLOOKUP('2965B'!Q11,Pilots[[SN Last 3]:[Pilot]],2,FALSE),"") | AB9: =IF('2965B'!$G$5=B9,"Max",IF('2965B'!$G$5=B8,"Lchs",""))
B10: 3 | C10: ='2965B'!B12 -> Bramwell | D10: ='2965B'!C12 -> Ansell | F10: ='2965B'!D12 -> SCT QGI | G10: ='2965B'!E12 -> 0.38888889 | H10: ='2965B'!F12 -> 0.40625 | I10: ='2965B'!G12 | J10: ='2965B'!H12 | K10: ='2965B'!I12 | L10: ='2965B'!N12 | M10: ='2965B'!K12 | N10: ='2965B'!J12 -> 0.017361111 | O10: =IF('2965B'!L12=TRUE,"ü","") | P10: =IF('2965B'!M12=TRUE,"ü","") -> ü | Q10: =IF('2965B'!S12=1,'2965B'!T12,"") | R10: =IF('2965B'!S12=2,'2965B'!T12,"") | S10: =IF('2965B'!S12=3,'2965B'!T12,"") | T10: =IF('2965B'!S12=4,'2965B'!T12,"") | U10: =IF('2965B'!S12=5,'2965B'!T12,"") | V10: =IF('2965B'!S12=6,'2965B'!T12,"") -> 0.017361111 | W10: =IF('2965B'!S12=7,'2965B'!T12,"") | X10: =IF('2965B'!S12=8,'2965B'!T12,"") | Y10: =IF(OR('2965B'!S12=2,'2965B'!S12=3,'2965B'!S12=4,'2965B'!S12=5),"ü","") | Z10: =IF('2965B'!P12=TRUE,"ü","") | AA10: =IFERROR(VLOOKUP('2965B'!Q12,Pilots[[SN Last 3]:[Pilot]],2,FALSE),"") -> JB | AB10: =IF('2965B'!$G$5=B10,"Max",IF('2965B'!$G$5=B9,"Lchs",""))
B11: 4 | C11: ='2965B'!B13 -> Bramwell | D11: ='2965B'!C13 -> Ansell | F11: ='2965B'!D13 -> SCT QGI | G11: ='2965B'!E13 -> 0.40972222 | H11: ='2965B'!F13 -> 0.41041667 | I11: ='2965B'!G13 | J11: ='2965B'!H13 | K11: ='2965B'!I13 | L11: ='2965B'!N13 | M11: ='2965B'!K13 | N11: ='2965B'!J13 -> 0.00069444444 | O11: =IF('2965B'!L13=TRUE,"ü","") | P11: =IF('2965B'!M13=TRUE,"ü","") -> ü | Q11: =IF('2965B'!S13=1,'2965B'!T13,"") -> 0.00069444444 | R11: =IF('2965B'!S13=2,'2965B'!T13,"") | S11: =IF('2965B'!S13=3,'2965B'!T13,"") | T11: =IF('2965B'!S13=4,'2965B'!T13,"") | U11: =IF('2965B'!S13=5,'2965B'!T13,"") | V11: =IF('2965B'!S13=6,'2965B'!T13,"") | W11: =IF('2965B'!S13=7,'2965B'!T13,"") | X11: =IF('2965B'!S13=8,'2965B'!T13,"") | Y11: =IF(OR('2965B'!S13=2,'2965B'!S13=3,'2965B'!S13=4,'2965B'!S13=5),"ü","") | Z11: =IF('2965B'!P13=TRUE,"ü","") -> ü | AA11: =IFERROR(VLOOKUP('2965B'!Q13,Pilots[[SN Last 3]:[Pilot]],2,FALSE),"") -> JB | AB11: =IF('2965B'!$G$5=B11,"Max",IF('2965B'!$G$5=B10,"Lchs",""))
B12: 5 | C12: ='2965B'!B14 -> Ashby | D12: ='2965B'!C14 -> Bloggs | F12: ='2965B'!D14 -> PAX | G12: ='2965B'!E14 -> 0.41666667 | H12: ='2965B'!F14 -> 0.42013889 | I12: ='2965B'!G14 | J12: ='2965B'!H14 | K12: ='2965B'!I14 | L12: ='2965B'!N14 -> 0.0034722222 | M12: ='2965B'!K14 | N12: ='2965B'!J14 | O12: =IF('2965B'!L14=TRUE,"ü","") | P12: =IF('2965B'!M14=TRUE,"ü","") | Q12: =IF('2965B'!S14=1,'2965B'!T14,"") -> 0.0034722222 | R12: =IF('2965B'!S14=2,'2965B'!T14,"") | S12: =IF('2965B'!S14=3,'2965B'!T14,"") | T12: =IF('2965B'!S14=4,'2965B'!T14,"") | U12: =IF('2965B'!S14=5,'2965B'!T14,"") | V12: =IF('2965B'!S14=6,'2965B'!T14,"") | W12: =IF('2965B'!S14=7,'2965B'!T14,"") | X12: =IF('2965B'!S14=8,'2965B'!T14,"") | Y12: =IF(OR('2965B'!S14=2,'2965B'!S14=3,'2965B'!S14=4,'2965B'!S14=5),"ü","") | Z12: =IF('2965B'!P14=TRUE,"ü","") | AA12: =IFERROR(VLOOKUP('2965B'!Q14,Pilots[[SN Last 3]:[Pilot]],2,FALSE),"") | AB12: =IF('2965B'!$G$5=B12,"Max",IF('2965B'!$G$5=B11,"Lchs",""))
B13: 6 | C13: ='2965B'!B15 -> 0 | D13: ='2965B'!C15 -> 0 | F13: ='2965B'!D15 -> 0 | G13: ='2965B'!E15 -> 0 | H13: ='2965B'!F15 -> 0 | I13: ='2965B'!G15 | J13: ='2965B'!H15 | K13: ='2965B'!I15 | L13: ='2965B'!N15 | M13: ='2965B'!K15 | N13: ='2965B'!J15 | O13: =IF('2965B'!L15=TRUE,"ü","") | P13: =IF('2965B'!M15=TRUE,"ü","") | Q13: =IF('2965B'!S15=1,'2965B'!T15,"") | R13: =IF('2965B'!S15=2,'2965B'!T15,"") | S13: =IF('2965B'!S15=3,'2965B'!T15,"") | T13: =IF('2965B'!S15=4,'2965B'!T15,"") | U13: =IF('2965B'!S15=5,'2965B'!T15,"") | V13: =IF('2965B'!S15=6,'2965B'!T15,"") | W13: =IF('2965B'!S15=7,'2965B'!T15,"") | X13: =IF('2965B'!S15=8,'2965B'!T15,"") | Y13: =IF(OR('2965B'!S15=2,'2965B'!S15=3,'2965B'!S15=4,'2965B'!S15=5),"ü","") | Z13: =IF('2965B'!P15=TRUE,"ü","") | AA13: =IFERROR(VLOOKUP('2965B'!Q15,Pilots[[SN Last 3]:[Pilot]],2,FALSE),"") | AB13: =IF('2965B'!$G$5=B13,"Max",IF('2965B'!$G$5=B12,"Lchs",""))
B14: 7 | C14: ='2965B'!B16 -> 0 | D14: ='2965B'!C16 -> 0 | F14: ='2965B'!D16 -> 0 | G14: ='2965B'!E16 -> 0 | H14: ='2965B'!F16 -> 0 | I14: ='2965B'!G16 | J14: ='2965B'!H16 | K14: ='2965B'!I16 | L14: ='2965B'!N16 | M14: ='2965B'!K16 | N14: ='2965B'!J16 | O14: =IF('2965B'!L16=TRUE,"ü","") | P14: =IF('2965B'!M16=TRUE,"ü","") | Q14: =IF('2965B'!S16=1,'2965B'!T16,"") | R14: =IF('2965B'!S16=2,'2965B'!T16,"") | S14: =IF('2965B'!S16=3,'2965B'!T16,"") | T14: =IF('2965B'!S16=4,'2965B'!T16,"") | U14: =IF('2965B'!S16=5,'2965B'!T16,"") | V14: =IF('2965B'!S16=6,'2965B'!T16,"") | W14: =IF('2965B'!S16=7,'2965B'!T16,"") | X14: =IF('2965B'!S16=8,'2965B'!T16,"") | Y14: =IF(OR('2965B'!S16=2,'2965B'!S16=3,'2965B'!S16=4,'2965B'!S16=5),"ü","") | Z14: =IF('2965B'!P16=TRUE,"ü","") | AA14: =IFERROR(VLOOKUP('2965B'!Q16,Pilots[[SN Last 3]:[Pilot]],2,FALSE),"") | AB14: =IF('2965B'!$G$5=B14,"Max",IF('2965B'!$G$5=B13,"Lchs",""))
B15: 8 | C15: ='2965B'!B17 -> 0 | D15: ='2965B'!C17 -> 0 | F15: ='2965B'!D17 -> 0 | G15: ='2965B'!E17 -> 0 | H15: ='2965B'!F17 -> 0 | I15: ='2965B'!G17 | J15: ='2965B'!H17 | K15: ='2965B'!I17 | L15: ='2965B'!N17 | M15: ='2965B'!K17 | N15: ='2965B'!J17 | O15: =IF('2965B'!L17=TRUE,"ü","") | P15: =IF('2965B'!M17=TRUE,"ü","") | Q15: =IF('2965B'!S17=1,'2965B'!T17,"") | R15: =IF('2965B'!S17=2,'2965B'!T17,"") | S15: =IF('2965B'!S17=3,'2965B'!T17,"") | T15: =IF('2965B'!S17=4,'2965B'!T17,"") | U15: =IF('2965B'!S17=5,'2965B'!T17,"") | V15: =IF('2965B'!S17=6,'2965B'!T17,"") | W15: =IF('2965B'!S17=7,'2965B'!T17,"") | X15: =IF('2965B'!S17=8,'2965B'!T17,"") | Y15: =IF(OR('2965B'!S17=2,'2965B'!S17=3,'2965B'!S17=4,'2965B'!S17=5),"ü","") | Z15: =IF('2965B'!P17=TRUE,"ü","") | AA15: =IFERROR(VLOOKUP('2965B'!Q17,Pilots[[SN Last 3]:[Pilot]],2,FALSE),"") | AB15: =IF('2965B'!$G$5=B15,"Max",IF('2965B'!$G$5=B14,"Lchs",""))
B16: 9 | C16: ='2965B'!B18 -> 0 | D16: ='2965B'!C18 -> 0 | F16: ='2965B'!D18 -> 0 | G16: ='2965B'!E18 -> 0 | H16: ='2965B'!F18 -> 0 | I16: ='2965B'!G18 | J16: ='2965B'!H18 | K16: ='2965B'!I18 | L16: ='2965B'!N18 | M16: ='2965B'!K18 | N16: ='2965B'!J18 | O16: =IF('2965B'!L18=TRUE,"ü","") | P16: =IF('2965B'!M18=TRUE,"ü","") | Q16: =IF('2965B'!S18=1,'2965B'!T18,"") | R16: =IF('2965B'!S18=2,'2965B'!T18,"") | S16: =IF('2965B'!S18=3,'2965B'!T18,"") | T16: =IF('2965B'!S18=4,'2965B'!T18,"") | U16: =IF('2965B'!S18=5,'2965B'!T18,"") | V16: =IF('2965B'!S18=6,'2965B'!T18,"") | W16: =IF('2965B'!S18=7,'2965B'!T18,"") | X16: =IF('2965B'!S18=8,'2965B'!T18,"") | Y16: =IF(OR('2965B'!S18=2,'2965B'!S18=3,'2965B'!S18=4,'2965B'!S18=5),"ü","") | Z16: =IF('2965B'!P18=TRUE,"ü","") | AA16: =IFERROR(VLOOKUP('2965B'!Q18,Pilots[[SN Last 3]:[Pilot]],2,FALSE),"") | AB16: =IF('2965B'!$G$5=B16,"Max",IF('2965B'!$G$5=B15,"Lchs",""))
B17: 10 | C17: ='2965B'!B19 -> 0 | D17: ='2965B'!C19 -> 0 | F17: ='2965B'!D19 -> 0 | G17: ='2965B'!E19 -> 0 | H17: ='2965B'!F19 -> 0 | I17: ='2965B'!G19 | J17: ='2965B'!H19 | K17: ='2965B'!I19 | L17: ='2965B'!N19 | M17: ='2965B'!K19 | N17: ='2965B'!J19 | O17: =IF('2965B'!L19=TRUE,"ü","") | P17: =IF('2965B'!M19=TRUE,"ü","") | Q17: =IF('2965B'!S19=1,'2965B'!T19,"") | R17: =IF('2965B'!S19=2,'2965B'!T19,"") | S17: =IF('2965B'!S19=3,'2965B'!T19,"") | T17: =IF('2965B'!S19=4,'2965B'!T19,"") | U17: =IF('2965B'!S19=5,'2965B'!T19,"") | V17: =IF('2965B'!S19=6,'2965B'!T19,"") | W17: =IF('2965B'!S19=7,'2965B'!T19,"") | X17: =IF('2965B'!S19=8,'2965B'!T19,"") | Y17: =IF(OR('2965B'!S19=2,'2965B'!S19=3,'2965B'!S19=4,'2965B'!S19=5),"ü","") | Z17: =IF('2965B'!P19=TRUE,"ü","") | AA17: =IFERROR(VLOOKUP('2965B'!Q19,Pilots[[SN Last 3]:[Pilot]],2,FALSE),"") | AB17: =IF('2965B'!$G$5=B17,"Max",IF('2965B'!$G$5=B16,"Lchs",""))
B18: 11 | C18: ='2965B'!B20 -> 0 | D18: ='2965B'!C20 -> 0 | F18: ='2965B'!D20 -> 0 | G18: ='2965B'!E20 -> 0 | H18: ='2965B'!F20 -> 0 | I18: ='2965B'!G20 | J18: ='2965B'!H20 | K18: ='2965B'!I20 | L18: ='2965B'!N20 | M18: ='2965B'!K20 | N18: ='2965B'!J20 | O18: =IF('2965B'!L20=TRUE,"ü","") | P18: =IF('2965B'!M20=TRUE,"ü","") | Q18: =IF('2965B'!S20=1,'2965B'!T20,"") | R18: =IF('2965B'!S20=2,'2965B'!T20,"") | S18: =IF('2965B'!S20=3,'2965B'!T20,"") | T18: =IF('2965B'!S20=4,'2965B'!T20,"") | U18: =IF('2965B'!S20=5,'2965B'!T20,"") | V18: =IF('2965B'!S20=6,'2965B'!T20,"") | W18: =IF('2965B'!S20=7,'2965B'!T20,"") | X18: =IF('2965B'!S20=8,'2965B'!T20,"") | Y18: =IF(OR('2965B'!S20=2,'2965B'!S20=3,'2965B'!S20=4,'2965B'!S20=5),"ü","") | Z18: =IF('2965B'!P20=TRUE,"ü","") | AA18: =IFERROR(VLOOKUP('2965B'!Q20,Pilots[[SN Last 3]:[Pilot]],2,FALSE),"") | AB18: =IF('2965B'!$G$5=B18,"Max",IF('2965B'!$G$5=B17,"Lchs",""))
B19: 12 | C19: ='2965B'!B21 -> 0 | D19: ='2965B'!C21 -> 0 | F19: ='2965B'!D21 -> 0 | G19: ='2965B'!E21 -> 0 | H19: ='2965B'!F21 -> 0 | I19: ='2965B'!G21 | J19: ='2965B'!H21 | K19: ='2965B'!I21 | L19: ='2965B'!N21 | M19: ='2965B'!K21 | N19: ='2965B'!J21 | O19: =IF('2965B'!L21=TRUE,"ü","") | P19: =IF('2965B'!M21=TRUE,"ü","") | Q19: =IF('2965B'!S21=1,'2965B'!T21,"") | R19: =IF('2965B'!S21=2,'2965B'!T21,"") | S19: =IF('2965B'!S21=3,'2965B'!T21,"") | T19: =IF('2965B'!S21=4,'2965B'!T21,"") | U19: =IF('2965B'!S21=5,'2965B'!T21,"") | V19: =IF('2965B'!S21=6,'2965B'!T21,"") | W19: =IF('2965B'!S21=7,'2965B'!T21,"") | X19: =IF('2965B'!S21=8,'2965B'!T21,"") | Y19: =IF(OR('2965B'!S21=2,'2965B'!S21=3,'2965B'!S21=4,'2965B'!S21=5),"ü","") | Z19: =IF('2965B'!P21=TRUE,"ü","") | AA19: =IFERROR(VLOOKUP('2965B'!Q21,Pilots[[SN Last 3]:[Pilot]],2,FALSE),"") | AB19: =IF('2965B'!$G$5=B19,"Max",IF('2965B'!$G$5=B18,"Lchs",""))
B20: 13 | C20: ='2965B'!B22 -> 0 | D20: ='2965B'!C22 -> 0 | F20: ='2965B'!D22 -> 0 | G20: ='2965B'!E22 -> 0 | H20: ='2965B'!F22 -> 0 | I20: ='2965B'!G22 | J20: ='2965B'!H22 | K20: ='2965B'!I22 | L20: ='2965B'!N22 | M20: ='2965B'!K22 | N20: ='2965B'!J22 | O20: =IF('2965B'!L22=TRUE,"ü","") | P20: =IF('2965B'!M22=TRUE,"ü","") | Q20: =IF('2965B'!S22=1,'2965B'!T22,"") | R20: =IF('2965B'!S22=2,'2965B'!T22,"") | S20: =IF('2965B'!S22=3,'2965B'!T22,"") | T20: =IF('2965B'!S22=4,'2965B'!T22,"") | U20: =IF('2965B'!S22=5,'2965B'!T22,"") | V20: =IF('2965B'!S22=6,'2965B'!T22,"") | W20: =IF('2965B'!S22=7,'2965B'!T22,"") | X20: =IF('2965B'!S22=8,'2965B'!T22,"") | Y20: =IF(OR('2965B'!S22=2,'2965B'!S22=3,'2965B'!S22=4,'2965B'!S22=5),"ü","") | Z20: =IF('2965B'!P22=TRUE,"ü","") | AA20: =IFERROR(VLOOKUP('2965B'!Q22,Pilots[[SN Last 3]:[Pilot]],2,FALSE),"") | AB20: =IF('2965B'!$G$5=B20,"Max",IF('2965B'!$G$5=B19,"Lchs",""))
... B25: 18 | C25: ='2965B'!B27 -> 0 | D25: ='2965B'!C27 -> 0 | F25: ='2965B'!D27 -> 0 | G25: ='2965B'!E27 -> 0 | H25: ='2965B'!F27 -> 0 | I25: ='2965B'!G27 | J25: ='2965B'!H27 | K25: ='2965B'!I27 | L25: ='2965B'!N27 | M25: ='2965B'!K27 | N25: ='2965B'!J27 | O25: =IF('2965B'!L27=TRUE,"ü","") | P25: =IF('2965B'!M27=TRUE,"ü","") | Q25: =IF('2965B'!S27=1,'2965B'!T27,"") | R25: =IF('2965B'!S27=2,'2965B'!T27,"") | S25: =IF('2965B'!S27=3,'2965B'!T27,"") | T25: =IF('2965B'!S27=4,'2965B'!T27,"") | U25: =IF('2965B'!S27=5,'2965B'!T27,"") | V25: =IF('2965B'!S27=6,'2965B'!T27,"") | W25: =IF('2965B'!S27=7,'2965B'!T27,"") | X25: =IF('2965B'!S27=8,'2965B'!T27,"") | Y25: =IF(OR('2965B'!S27=2,'2965B'!S27=3,'2965B'!S27=4,'2965B'!S27=5),"ü","") | Z25: =IF('2965B'!P27=TRUE,"ü","") | AA25: =IFERROR(VLOOKUP('2965B'!Q27,Pilots[[SN Last 3]:[Pilot]],2,FALSE),"") | AB25: =IF('2965B'!$G$5=B25,"Max",IF('2965B'!$G$5=B24,"Lchs",""))
B26: S P C | C26: 1. Winch Launch (Circuit) 2. Aerotow Only 3. Aerotow + Soaring 4. Aerotow + Stalling | D26: 5. Aerotow + Aeros 6. Winch Launch + Soaring 7. Winch Launch + Aeros 8. Maintenance Flight Test | F26: Carry Forward | G26: Launches: | I26: =COUNT(I8:I25) -> 2 | J26: =COUNT(J8:J25) -> 0 | K26: =COUNT(K8:K25) -> 0 | L26: =COUNT(L8:L25) -> 1 | M26: =COUNT(M8:M25) -> 0 | N26: =COUNT(N8:N25) -> 2 | Q26: =COUNT(Q8:Q25) -> 4 | R26: =COUNT(R8:R25) -> 0 | S26: =COUNT(S8:S25) -> 0 | T26: =COUNT(T8:T25) -> 0 | U26: =COUNT(U8:U25) -> 0 | V26: =COUNT(V8:V25) -> 1 | W26: =COUNT(W8:W25) -> 0 | X26: =COUNT(X8:X25) -> 0
G27: Flying Hours: | I27: =SUM(I8:I25) -> 0.0069444444 | J27: =SUM(J8:J25) -> 0 | K27: =SUM(K8:K25) -> 0 | L27: =SUM(L8:L25) -> 0.0034722222 | M27: =SUM(M8:M25) -> 0 | N27: =SUM(N8:N25) -> 0.018055556 | Q27: =SUM(Q8:Q25) -> 0.011111111 | R27: =SUM(R8:R25) -> 0 | S27: =SUM(S8:S25) -> 0 | T27: =SUM(T8:T25) -> 0 | U27: =SUM(U8:U25) -> 0 | V27: =SUM(V8:V25) -> 0.017361111 | W27: =SUM(W8:W25) -> 0 | X27: =SUM(X8:X25) -> 0
B28: Produced by Air Media Centre, HQ Air Command, © UK MOD Crown Copyright | Y28: Page 1 of 2
B31: RAF Glider Flying Times Continuation Sheet | H31: A/C Number: | J31: =O2 -> ZE495 | L31: A/C Tail Letters: | P31: =V2 -> VA | X31: RAF Form 2965B (Revised 8/26)
B33: ACTION AFTER FLIGHT HAS COMMENCED - TO BE COMPLETED IAW 2 FTS DUTY HOLDER ORDERS (DHOs) 2401(5)
B34: Serial No of Flight | C34: (Individuals with the same surname should have their forename initial added after their surname) | F34: Duty (GIF, GS, AGT, SCT, JSAT, PAX etc) | G34: Time of Take-Off | H34: Time of Landing | I34: Trainee (Hours:Min) | L34: Other Flying (Hours:Min) | M34: SCT | Q34: Sortie Profile Codes (SPC) (Aircraft Commander to complete) (Hours:Min) | Y34: Aerotow (ü) | Z34: PLF (ü) | AA34: After Flight Initials
M35: (Hours:Min) | O35: Claimed By (ü)
C36: Surname of Aircraft Commander | D36: Surname of Second Pilot, Trainee or PAX | I36: GIF | J36: G/S | K36: AGT | M36: U/T | N36: QGI | O36: P1 | P36: P2 | Q36: 1 | R36: 2 | S36: 3 | T36: 4 | U36: 5 | V36: 6 | W36: 7 | X36: 8
F37: Brought Forward | G37: Launches: | I37: =I26 -> 2 | J37: =J26 -> 0 | K37: =K26 -> 0 | L37: =L26 -> 1 | M37: =M26 -> 0 | N37: =N26 -> 2 | Q37: =Q26 -> 4 | R37: =R26 -> 0 | S37: =S26 -> 0 | T37: =T26 -> 0 | U37: =U26 -> 0 | V37: =V26 -> 1 | W37: =W26 -> 0 | X37: =X26 -> 0
G38: Flying Hours: | I38: =I27 -> 0.0069444444 | J38: =J27 -> 0 | K38: =K27 -> 0 | L38: =L27 -> 0.0034722222 | M38: =M27 -> 0 | N38: =N27 -> 0.018055556 | Q38: =Q27 -> 0.011111111 | R38: =R27 -> 0 | S38: =S27 -> 0 | T38: =T27 -> 0 | U38: =U27 -> 0 | V38: =V27 -> 0.017361111 | W38: =W27 -> 0 | X38: =X27 -> 0
B39: 19 | C39: ='2965B'!B28 -> 0 | D39: ='2965B'!C28 -> 0 | F39: ='2965B'!D28 -> 0 | G39: ='2965B'!E28 -> 0 | H39: ='2965B'!F28 -> 0 | I39: ='2965B'!G28 | J39: ='2965B'!H28 | K39: ='2965B'!I28 | L39: ='2965B'!N28 | M39: ='2965B'!K28 | N39: ='2965B'!J28 | O39: =IF('2965B'!L28=TRUE,"ü","") | P39: =IF('2965B'!M28=TRUE,"ü","") | Q39: =IF('2965B'!$S28=1,'2965B'!$T28,"") | R39: =IF('2965B'!$S28=2,'2965B'!$T28,"") | S39: =IF('2965B'!$S28=3,'2965B'!$T28,"") | T39: =IF('2965B'!$S28=4,'2965B'!$T28,"") | U39: =IF('2965B'!$S28=5,'2965B'!$T28,"") | V39: =IF('2965B'!$S28=6,'2965B'!$T28,"") | W39: =IF('2965B'!$S28=7,'2965B'!$T28,"") | X39: =IF('2965B'!$S28=8,'2965B'!$T28,"") | Y39: =IF(OR('2965B'!S28=2,'2965B'!S28=3,'2965B'!S28=4,'2965B'!S28=5),"ü","") | Z39: =IF('2965B'!P28=TRUE,"ü","") | AA39: =IFERROR(VLOOKUP('2965B'!Q28,Pilots[[SN Last 3]:[Pilot]],2,FALSE),"") | AB39: =IF('2965B'!$G$5=B39,"Max","")
B40: 20 | C40: ='2965B'!B29 -> 0 | D40: ='2965B'!C29 -> 0 | F40: ='2965B'!D29 -> 0 | G40: ='2965B'!E29 -> 0 | H40: ='2965B'!F29 -> 0 | I40: ='2965B'!G29 | J40: ='2965B'!H29 | K40: ='2965B'!I29 | L40: ='2965B'!N29 | M40: ='2965B'!K29 | N40: ='2965B'!J29 | O40: =IF('2965B'!L29=TRUE,"ü","") | P40: =IF('2965B'!M29=TRUE,"ü","") | Q40: =IF('2965B'!$S29=1,'2965B'!$T29,"") | R40: =IF('2965B'!$S29=2,'2965B'!$T29,"") | S40: =IF('2965B'!$S29=3,'2965B'!$T29,"") | T40: =IF('2965B'!$S29=4,'2965B'!$T29,"") | U40: =IF('2965B'!$S29=5,'2965B'!$T29,"") | V40: =IF('2965B'!$S29=6,'2965B'!$T29,"") | W40: =IF('2965B'!$S29=7,'2965B'!$T29,"") | X40: =IF('2965B'!$S29=8,'2965B'!$T29,"") | Y40: =IF(OR('2965B'!S29=2,'2965B'!S29=3,'2965B'!S29=4,'2965B'!S29=5),"ü","") | Z40: =IF('2965B'!P29=TRUE,"ü","") | AA40: =IFERROR(VLOOKUP('2965B'!Q29,Pilots[[SN Last 3]:[Pilot]],2,FALSE),"") | AB40: =IF('2965B'!$G$5=B40,"Max",IF('2965B'!$G$5=B39,"Lchs",""))
B41: 21 | C41: ='2965B'!B30 -> 0 | D41: ='2965B'!C30 -> 0 | F41: ='2965B'!D30 -> 0 | G41: ='2965B'!E30 -> 0 | H41: ='2965B'!F30 -> 0 | I41: ='2965B'!G30 | J41: ='2965B'!H30 | K41: ='2965B'!I30 | L41: ='2965B'!N30 | M41: ='2965B'!K30 | N41: ='2965B'!J30 | O41: =IF('2965B'!L30=TRUE,"ü","") | P41: =IF('2965B'!M30=TRUE,"ü","") | Q41: =IF('2965B'!$S30=1,'2965B'!$T30,"") | R41: =IF('2965B'!$S30=2,'2965B'!$T30,"") | S41: =IF('2965B'!$S30=3,'2965B'!$T30,"") | T41: =IF('2965B'!$S30=4,'2965B'!$T30,"") | U41: =IF('2965B'!$S30=5,'2965B'!$T30,"") | V41: =IF('2965B'!$S30=6,'2965B'!$T30,"") | W41: =IF('2965B'!$S30=7,'2965B'!$T30,"") | X41: =IF('2965B'!$S30=8,'2965B'!$T30,"") | Y41: =IF(OR('2965B'!S30=2,'2965B'!S30=3,'2965B'!S30=4,'2965B'!S30=5),"ü","") | Z41: =IF('2965B'!P30=TRUE,"ü","") | AA41: =IFERROR(VLOOKUP('2965B'!Q30,Pilots[[SN Last 3]:[Pilot]],2,FALSE),"") | AB41: =IF('2965B'!$G$5=B41,"Max",IF('2965B'!$G$5=B40,"Lchs",""))
B42: 22 | C42: ='2965B'!B31 -> 0 | D42: ='2965B'!C31 -> 0 | F42: ='2965B'!D31 -> 0 | G42: ='2965B'!E31 -> 0 | H42: ='2965B'!F31 -> 0 | I42: ='2965B'!G31 | J42: ='2965B'!H31 | K42: ='2965B'!I31 | L42: ='2965B'!N31 | M42: ='2965B'!K31 | N42: ='2965B'!J31 | O42: =IF('2965B'!L31=TRUE,"ü","") | P42: =IF('2965B'!M31=TRUE,"ü","") | Q42: =IF('2965B'!$S31=1,'2965B'!$T31,"") | R42: =IF('2965B'!$S31=2,'2965B'!$T31,"") | S42: =IF('2965B'!$S31=3,'2965B'!$T31,"") | T42: =IF('2965B'!$S31=4,'2965B'!$T31,"") | U42: =IF('2965B'!$S31=5,'2965B'!$T31,"") | V42: =IF('2965B'!$S31=6,'2965B'!$T31,"") | W42: =IF('2965B'!$S31=7,'2965B'!$T31,"") | X42: =IF('2965B'!$S31=8,'2965B'!$T31,"") | Y42: =IF(OR('2965B'!S31=2,'2965B'!S31=3,'2965B'!S31=4,'2965B'!S31=5),"ü","") | Z42: =IF('2965B'!P31=TRUE,"ü","") | AA42: =IFERROR(VLOOKUP('2965B'!Q31,Pilots[[SN Last 3]:[Pilot]],2,FALSE),"") | AB42: =IF('2965B'!$G$5=B42,"Max",IF('2965B'!$G$5=B41,"Lchs",""))
B43: 23 | C43: ='2965B'!B32 -> 0 | D43: ='2965B'!C32 -> 0 | F43: ='2965B'!D32 -> 0 | G43: ='2965B'!E32 -> 0 | H43: ='2965B'!F32 -> 0 | I43: ='2965B'!G32 | J43: ='2965B'!H32 | K43: ='2965B'!I32 | L43: ='2965B'!N32 | M43: ='2965B'!K32 | N43: ='2965B'!J32 | O43: =IF('2965B'!L32=TRUE,"ü","") | P43: =IF('2965B'!M32=TRUE,"ü","") | Q43: =IF('2965B'!$S32=1,'2965B'!$T32,"") | R43: =IF('2965B'!$S32=2,'2965B'!$T32,"") | S43: =IF('2965B'!$S32=3,'2965B'!$T32,"") | T43: =IF('2965B'!$S32=4,'2965B'!$T32,"") | U43: =IF('2965B'!$S32=5,'2965B'!$T32,"") | V43: =IF('2965B'!$S32=6,'2965B'!$T32,"") | W43: =IF('2965B'!$S32=7,'2965B'!$T32,"") | X43: =IF('2965B'!$S32=8,'2965B'!$T32,"") | Y43: =IF(OR('2965B'!S32=2,'2965B'!S32=3,'2965B'!S32=4,'2965B'!S32=5),"ü","") | Z43: =IF('2965B'!P32=TRUE,"ü","") | AA43: =IFERROR(VLOOKUP('2965B'!Q32,Pilots[[SN Last 3]:[Pilot]],2,FALSE),"") | AB43: =IF('2965B'!$G$5=B43,"Max",IF('2965B'!$G$5=B42,"Lchs",""))
B44: 24 | C44: ='2965B'!B33 -> 0 | D44: ='2965B'!C33 -> 0 | F44: ='2965B'!D33 -> 0 | G44: ='2965B'!E33 -> 0 | H44: ='2965B'!F33 -> 0 | I44: ='2965B'!G33 | J44: ='2965B'!H33 | K44: ='2965B'!I33 | L44: ='2965B'!N33 | M44: ='2965B'!K33 | N44: ='2965B'!J33 | O44: =IF('2965B'!L33=TRUE,"ü","") | P44: =IF('2965B'!M33=TRUE,"ü","") | Q44: =IF('2965B'!$S33=1,'2965B'!$T33,"") | R44: =IF('2965B'!$S33=2,'2965B'!$T33,"") | S44: =IF('2965B'!$S33=3,'2965B'!$T33,"") | T44: =IF('2965B'!$S33=4,'2965B'!$T33,"") | U44: =IF('2965B'!$S33=5,'2965B'!$T33,"") | V44: =IF('2965B'!$S33=6,'2965B'!$T33,"") | W44: =IF('2965B'!$S33=7,'2965B'!$T33,"") | X44: =IF('2965B'!$S33=8,'2965B'!$T33,"") | Y44: =IF(OR('2965B'!S33=2,'2965B'!S33=3,'2965B'!S33=4,'2965B'!S33=5),"ü","") | Z44: =IF('2965B'!P33=TRUE,"ü","") | AA44: =IFERROR(VLOOKUP('2965B'!Q33,Pilots[[SN Last 3]:[Pilot]],2,FALSE),"") | AB44: =IF('2965B'!$G$5=B44,"Max",IF('2965B'!$G$5=B43,"Lchs",""))
B45: 25 | C45: ='2965B'!B34 -> 0 | D45: ='2965B'!C34 -> 0 | F45: ='2965B'!D34 -> 0 | G45: ='2965B'!E34 -> 0 | H45: ='2965B'!F34 -> 0 | I45: ='2965B'!G34 | J45: ='2965B'!H34 | K45: ='2965B'!I34 | L45: ='2965B'!N34 | M45: ='2965B'!K34 | N45: ='2965B'!J34 | O45: =IF('2965B'!L34=TRUE,"ü","") | P45: =IF('2965B'!M34=TRUE,"ü","") | Q45: =IF('2965B'!$S34=1,'2965B'!$T34,"") | R45: =IF('2965B'!$S34=2,'2965B'!$T34,"") | S45: =IF('2965B'!$S34=3,'2965B'!$T34,"") | T45: =IF('2965B'!$S34=4,'2965B'!$T34,"") | U45: =IF('2965B'!$S34=5,'2965B'!$T34,"") | V45: =IF('2965B'!$S34=6,'2965B'!$T34,"") | W45: =IF('2965B'!$S34=7,'2965B'!$T34,"") | X45: =IF('2965B'!$S34=8,'2965B'!$T34,"") | Y45: =IF(OR('2965B'!S34=2,'2965B'!S34=3,'2965B'!S34=4,'2965B'!S34=5),"ü","") | Z45: =IF('2965B'!P34=TRUE,"ü","") | AA45: =IFERROR(VLOOKUP('2965B'!Q34,Pilots[[SN Last 3]:[Pilot]],2,FALSE),"") | AB45: =IF('2965B'!$G$5=B45,"Max",IF('2965B'!$G$5=B44,"Lchs",""))
B46: 26 | C46: ='2965B'!B35 -> 0 | D46: ='2965B'!C35 -> 0 | F46: ='2965B'!D35 -> 0 | G46: ='2965B'!E35 -> 0 | H46: ='2965B'!F35 -> 0 | I46: ='2965B'!G35 | J46: ='2965B'!H35 | K46: ='2965B'!I35 | L46: ='2965B'!N35 | M46: ='2965B'!K35 | N46: ='2965B'!J35 | O46: =IF('2965B'!L35=TRUE,"ü","") | P46: =IF('2965B'!M35=TRUE,"ü","") | Q46: =IF('2965B'!$S35=1,'2965B'!$T35,"") | R46: =IF('2965B'!$S35=2,'2965B'!$T35,"") | S46: =IF('2965B'!$S35=3,'2965B'!$T35,"") | T46: =IF('2965B'!$S35=4,'2965B'!$T35,"") | U46: =IF('2965B'!$S35=5,'2965B'!$T35,"") | V46: =IF('2965B'!$S35=6,'2965B'!$T35,"") | W46: =IF('2965B'!$S35=7,'2965B'!$T35,"") | X46: =IF('2965B'!$S35=8,'2965B'!$T35,"") | Y46: =IF(OR('2965B'!S35=2,'2965B'!S35=3,'2965B'!S35=4,'2965B'!S35=5),"ü","") | Z46: =IF('2965B'!P35=TRUE,"ü","") | AA46: =IFERROR(VLOOKUP('2965B'!Q35,Pilots[[SN Last 3]:[Pilot]],2,FALSE),"") | AB46: =IF('2965B'!$G$5=B46,"Max",IF('2965B'!$G$5=B45,"Lchs",""))
B47: 27 | C47: ='2965B'!B36 -> 0 | D47: ='2965B'!C36 -> 0 | F47: ='2965B'!D36 -> 0 | G47: ='2965B'!E36 -> 0 | H47: ='2965B'!F36 -> 0 | I47: ='2965B'!G36 | J47: ='2965B'!H36 | K47: ='2965B'!I36 | L47: ='2965B'!N36 | M47: ='2965B'!K36 | N47: ='2965B'!J36 | O47: =IF('2965B'!L36=TRUE,"ü","") | P47: =IF('2965B'!M36=TRUE,"ü","") | Q47: =IF('2965B'!$S36=1,'2965B'!$T36,"") | R47: =IF('2965B'!$S36=2,'2965B'!$T36,"") | S47: =IF('2965B'!$S36=3,'2965B'!$T36,"") | T47: =IF('2965B'!$S36=4,'2965B'!$T36,"") | U47: =IF('2965B'!$S36=5,'2965B'!$T36,"") | V47: =IF('2965B'!$S36=6,'2965B'!$T36,"") | W47: =IF('2965B'!$S36=7,'2965B'!$T36,"") | X47: =IF('2965B'!$S36=8,'2965B'!$T36,"") | Y47: =IF(OR('2965B'!S36=2,'2965B'!S36=3,'2965B'!S36=4,'2965B'!S36=5),"ü","") | Z47: =IF('2965B'!P36=TRUE,"ü","") | AA47: =IFERROR(VLOOKUP('2965B'!Q36,Pilots[[SN Last 3]:[Pilot]],2,FALSE),"") | AB47: =IF('2965B'!$G$5=B47,"Max",IF('2965B'!$G$5=B46,"Lchs",""))
B48: 28 | C48: ='2965B'!B37 -> 0 | D48: ='2965B'!C37 -> 0 | F48: ='2965B'!D37 -> 0 | G48: ='2965B'!E37 -> 0 | H48: ='2965B'!F37 -> 0 | I48: ='2965B'!G37 | J48: ='2965B'!H37 | K48: ='2965B'!I37 | L48: ='2965B'!N37 | M48: ='2965B'!K37 | N48: ='2965B'!J37 | O48: =IF('2965B'!L37=TRUE,"ü","") | P48: =IF('2965B'!M37=TRUE,"ü","") | Q48: =IF('2965B'!$S37=1,'2965B'!$T37,"") | R48: =IF('2965B'!$S37=2,'2965B'!$T37,"") | S48: =IF('2965B'!$S37=3,'2965B'!$T37,"") | T48: =IF('2965B'!$S37=4,'2965B'!$T37,"") | U48: =IF('2965B'!$S37=5,'2965B'!$T37,"") | V48: =IF('2965B'!$S37=6,'2965B'!$T37,"") | W48: =IF('2965B'!$S37=7,'2965B'!$T37,"") | X48: =IF('2965B'!$S37=8,'2965B'!$T37,"") | Y48: =IF(OR('2965B'!S37=2,'2965B'!S37=3,'2965B'!S37=4,'2965B'!S37=5),"ü","") | Z48: =IF('2965B'!P37=TRUE,"ü","") | AA48: =IFERROR(VLOOKUP('2965B'!Q37,Pilots[[SN Last 3]:[Pilot]],2,FALSE),"") | AB48: =IF('2965B'!$G$5=B48,"Max",IF('2965B'!$G$5=B47,"Lchs",""))
B49: 29 | C49: ='2965B'!B38 -> 0 | D49: ='2965B'!C38 -> 0 | F49: ='2965B'!D38 -> 0 | G49: ='2965B'!E38 -> 0 | H49: ='2965B'!F38 -> 0 | I49: ='2965B'!G38 | J49: ='2965B'!H38 | K49: ='2965B'!I38 | L49: ='2965B'!N38 | M49: ='2965B'!K38 | N49: ='2965B'!J38 | O49: =IF('2965B'!L38=TRUE,"ü","") | P49: =IF('2965B'!M38=TRUE,"ü","") | Q49: =IF('2965B'!$S38=1,'2965B'!$T38,"") | R49: =IF('2965B'!$S38=2,'2965B'!$T38,"") | S49: =IF('2965B'!$S38=3,'2965B'!$T38,"") | T49: =IF('2965B'!$S38=4,'2965B'!$T38,"") | U49: =IF('2965B'!$S38=5,'2965B'!$T38,"") | V49: =IF('2965B'!$S38=6,'2965B'!$T38,"") | W49: =IF('2965B'!$S38=7,'2965B'!$T38,"") | X49: =IF('2965B'!$S38=8,'2965B'!$T38,"") | Y49: =IF(OR('2965B'!S38=2,'2965B'!S38=3,'2965B'!S38=4,'2965B'!S38=5),"ü","") | Z49: =IF('2965B'!P38=TRUE,"ü","") | AA49: =IFERROR(VLOOKUP('2965B'!Q38,Pilots[[SN Last 3]:[Pilot]],2,FALSE),"") | AB49: =IF('2965B'!$G$5=B49,"Max",IF('2965B'!$G$5=B48,"Lchs","")) -> Max
...

Sheet F724 Guide
B1: Date | C1: Daily Total Hours | E1: Daily Total Lchs | J1: Captains Name | K1: Data Present
B2: ='2965B'!$O$2 -> 46275 | C2: ='2965B'!N$44 -> 0 | D2: =D14+C2 -> 83.333333 | E2: ='2965B'!N45 -> 0 | F2: =F14+E2 -> 2000 | G2: As Req'd | H2: As Req'd | I2: 8 | J2: {=_xlfn.XLOOKUP(1,1/('2965B'!B10:B39<>""),'2965B'!B10:B39,"",,-1)} -> Ashby | K2: =IF(E2>0,TRUE,FALSE) -> FALSE
B3: ='2965B'!$O$2 -> 46275 | C3: ='2965B'!M$44 -> 0 | D3: =D2+C3 -> 83.333333 | E3: ='2965B'!M45 -> 0 | F3: =F2+E3 -> 2000 | G3: As Req'd | H3: As Req'd | I3: 7 | J3: =J2 -> Ashby | K3: =IF(E3>0,TRUE,FALSE) -> FALSE
B4: ='2965B'!$O$2 -> 46275 | C4: ='2965B'!L$44 -> 0.017361111 | D4: =D3+C4 -> 83.350694 | E4: ='2965B'!L45 -> 1 | F4: =F3+E4 -> 2001 | G4: As Req'd | H4: As Req'd | I4: 6 | J4: =J3 -> Ashby | K4: =IF(E4>0,TRUE,FALSE) -> TRUE
B5: ='2965B'!$O$2 -> 46275 | C5: ='2965B'!K$44 -> 0 | D5: =D4+C5 -> 83.350694 | E5: ='2965B'!K45 -> 0 | F5: =F4+E5 -> 2001 | G5: As Req'd | H5: As Req'd | I5: 5 | J5: =J4 -> Ashby | K5: =IF(E5>0,TRUE,FALSE) -> FALSE
B6: ='2965B'!$O$2 -> 46275 | C6: ='2965B'!J$44 -> 0 | D6: =D5+C6 -> 83.350694 | E6: ='2965B'!J45 -> 0 | F6: =F5+E6 -> 2001 | G6: As Req'd | H6: As Req'd | I6: 4 | J6: =J5 -> Ashby | K6: =IF(E6>0,TRUE,FALSE) -> FALSE
B7: ='2965B'!$O$2 -> 46275 | C7: ='2965B'!I$44 -> 0 | D7: =D6+C7 -> 83.350694 | E7: ='2965B'!I45 -> 0 | F7: =F6+E7 -> 2001 | G7: As Req'd | H7: As Req'd | I7: 3 | J7: =J6 -> Ashby | K7: =IF(E7>0,TRUE,FALSE) -> FALSE
B8: ='2965B'!$O$2 -> 46275 | C8: ='2965B'!H$44 -> 0 | D8: =D7+C8 -> 83.350694 | E8: ='2965B'!H45 -> 0 | F8: =F7+E8 -> 2001 | G8: As Req'd | H8: As Req'd | I8: 2 | J8: =J7 -> Ashby | K8: =IF(E8>0,TRUE,FALSE) -> FALSE
B9: ='2965B'!$O$2 -> 46275 | C9: ='2965B'!G$44 -> 0.011111111 | D9: =D8+C9 -> 83.361806 | E9: ='2965B'!G45 -> 4 | F9: =F8+E9 -> 2005 | G9: As Req'd | H9: As Req'd | I9: 1 | J9: =J8 -> Ashby | K9: =IF(E9>0,TRUE,FALSE) -> TRUE
A10: F724 Running Log Guide
B12: Date | C12: Hours Flown | E12: Launches | G12: Spins | I12: Sortie Profile Codes | J12: Captain's Printed Name
C13: Daily Total | D13: Total | E13: Daily Total | F13: Total | G13: Daily Total | H13: Total
A14: Previous Entry | D14: ='2965B'!C4 -> 83.333333 | F14: ='2965B'!C5 -> 2000
A15: Start from this Line | B15: {=_xlfn._xlws.FILTER(B2:K9,K2:K9=TRUE,"")} -> 46275 | C15: 0.017361111 | D15: 83.350694 | E15: 1 | F15: 2001 | G15: As Req'd | H15: As Req'd | I15: 6 | J15: Ashby | K15: TRUE
B16: 46275 | C16: 0.011111111 | D16: 83.361806 | E16: 4 | F16: 2005 | G16: As Req'd | H16: As Req'd | I16: 1 | J16: Ashby | K16: TRUE

Sheet Instructions
A1: Start of Day
A2: 1 | B2: Save the file to Sharepoint and name it "2965B_DATE_AIRCRAFT.xlsx" e.g. 2965B_250211_ZE625.xlsx
A3: 2 | B3: Enter aircraft number and date along the top
A4: 3 | B4: Add launches and hours before flight from the F724.
A5: 4 | B5: Add the last three digits of the AC commander into the AF initials column during the in-brief.
A7: End of Day
A8: 1 | B8: Ensure the log sheet has saved to Sharepoint
A9: 2 | B9: Login to the VGS Stats Dashboard
A10: 3 | B10: Upload log sheets on the "Upload Log Sheets" page
A11: 4 | B11: Go to "Print Copy" and print the log sheet.
B13: If you really need to, the editing password for this document is "Viking"

Sheet Changelog
A1: Version | B1: Date | C1: Name | D1: Changes
A2: 1.1.0 | B2: 45027 | C2: MJ | D2: Updated SPC column to be 6 if time flown is > 9 min 30 seconds. Added CGS names into aircraft commander columns Added changelog Updated instructions with hyperlinks and next steps
A3: 1.2.0 | B3: 45030 | C3: MJ | D3: Added checkboxes to PLF columns. FORMATTED now returns TRUE or FALSE.
A4: 1.3.1 | B4: 45074 | C4: MJ | D4: Added pilots
A5: 1.4.0 | B5: 45088 | C5: CW | D5: Instruction (7) updated Extra instructions added Tickboxes added to P1 and P2 columns Duty drop down list updated Duty column headers updated on the 2965D FORMATTED table P1 and P2 columns added
A6: 1.4.1 | B6: 45101 | C6: CW | D6: Added pilot and aircraft. Various formula's updated to reflect weaknesses in new duty names and full sheets
A7: 1.4.2 | B7: 45136 | C7: MJ | D7: Fixed formula in total launches boxes using COUNTA instead of 23-COUNTBLANK. Changed duty back to G/S, AGT. Simpified instructions. Added locked cells and password-protected sheet.
A8: 2.0.0 | B8: 45112 | C8: DA | D8: Major changes to template: Added F724 entry guide Added Print Copy for if required to print log sheet
A9: 2.1.0 | B9: 45513 | C9: DA | D9: Added formatting to display max launches left
A10: 2.2.0 | B10: 45522 | C10: MJ | D10: Fixed print area on Print Copy Print copy cells no longer show 0 when the sheet is blank Fixed typo in 724 B/F cell
A11: 2.3.0 | B11: 45560 | C11: MJ | D11: Added _AIRCRAFT to capture hours and launches after flight Updated instructions with hyperlinks
A12: 2.3.1 | B12: 45564 | C12: MJ | D12: Fixed _AIRCRAFT hours and launches pulling from the wrong fields
A13: 2.3.2 | B13: 45564 | C13: MJ | D13: Fixed launches column in _AIRCRAFT pulling from the hours row
... A25: 4.1.0 | B25: 46275 | C25: MJ | D25: Take-off and landing times now plain times; the dashboard adds the date. Fixed the broken _AIRCRAFT hours and launches formulas. Aerotow tick box removed; it is now worked out from the sortie profile code. Drop-downs now read the INPUT_DATA tables, so adding a row is enough. Landing time must now be after take-off, and take-off after the previous landing. Removed the sample data, the stray drop-down on F3 and the stray rule on G10.

Sheet INPUT_DATA
A1: Number | B1: Tail Letter | D1: Duty | F1: SPC Codes
A2: ZE528 | B2: VQ | D2: GIF | F2: 1 - Winch Launch (Circuit)
A3: ZE495 | B3: VA | D3: G/S | F3: 2 - Aerotow Only
A4: ZE602 | B4: XB | D4: AGT | F4: 3 - Aerotow + Soaring
A5: ZE625 | B5: XP | D5: SCT QGI | F5: 4 - Aerotow + Stalling
A6: ZE527 | B6: VP | D6: SCT U/T | F6: 5 - Aerotow + Aeros
A7: ZE633 | B7: XX | D7: PAX | F7: 6 - Winch Launch + Soaring
A8: ZE529 | B8: VR | F8: 7 - Winch Launch + Aeros
A9: ZE683 | B9: YT | F9: 8 - Maintenance Flight Test
A10: ZE626 | B10: XQ
A11: ZE557 | B11: WE
A12: ZE551 | B12: VY
A16: SN Last 3 | B16: Pilot | C16: Surname
A17: 481 | B17: DA | C17: Ansell
A18: 250 | B18: IA | C18: Ashby
A19: 097 | B19: SA | C19: Attwood
A20: 068 | B20: AB | C20: Bagley
A21: 315 | B21: JB | C21: Bramwell
B22: SB | C22: Broadhurst
A23: 736 | B23: KC | C23: Corfield, K
B24: CD | C24: Dunmore
B25: HE | C25: Ellwood
A26: 129 | B26: KG | C26: Garnett
B27: SG | C27: Grantley
A28: 842 | B28: MJ | C28: Jarrold
A29: 054 | B29: GJ | C29: Jessop
A30: 71C | B30: CL | C30: Ledbury
B31: SL | C31: Lomax
B32: AM | C32: Marchant
A33: 368 | B33: AM | C33: Merrifield
A34: 025 | B34: LM | C34: Millward
A35: 490 | B35: JP | C35: Pentland
B36: NP | C36: Pickford
A37: 617 | B37: LP | C37: Pollard
A38: 183 | B38: AR | C38: Rossiter
A39: 902 | B39: PS | C39: Stannard
A40: 534 | B40: KT | C40: Thorne
A41: 726 | B41: CW | C41: Winslow, C
B42: RW | C42: Winslow, R
B43: TW | C43: Woolley
...

Sheet FORMATTED
A1: AircraftCommander | B1: 2ndPilot | C1: Duty | D1: TakeOffTime | E1: LandingTime | F1: FlightTime | G1: SPC | H1: PLF | I1: Aircraft | J1: Date | K1: P1 | L1: P2
A2: ='2965B'!B10 -> Jarrold | B2: ='2965B'!C10 -> Bloggs | C2: ='2965B'!D10 -> GIF | D2: ='2965B'!E10 -> 0.375 | E2: ='2965B'!F10 -> 0.37847222 | F2: =ROUND((Table10[[#This Row],[LandingTime]]-Table10[[#This Row],[TakeOffTime]])*1440,0) -> 5 | G2: ='2965B'!S10 -> 1 | H2: ='2965B'!P10 -> FALSE | I2: ='2965B'!$F$2 -> ZE495 | J2: ='2965B'!$O$2 -> 46275 | K2: ='2965B'!L10 -> FALSE | L2: ='2965B'!M10 -> FALSE
A3: ='2965B'!B11 -> Winslow, C | B3: ='2965B'!C11 -> Joe | C3: ='2965B'!D11 -> GIF | D3: ='2965B'!E11 -> 0.38194444 | E3: ='2965B'!F11 -> 0.38541667 | F3: =ROUND((Table10[[#This Row],[LandingTime]]-Table10[[#This Row],[TakeOffTime]])*1440,0) -> 5 | G3: ='2965B'!S11 -> 1 | H3: ='2965B'!P11 -> FALSE | I3: ='2965B'!$F$2 -> ZE495 | J3: ='2965B'!$O$2 -> 46275 | K3: ='2965B'!L11 -> FALSE | L3: ='2965B'!M11 -> FALSE
A4: ='2965B'!B12 -> Bramwell | B4: ='2965B'!C12 -> Ansell | C4: ='2965B'!D12 -> SCT QGI | D4: ='2965B'!E12 -> 0.38888889 | E4: ='2965B'!F12 -> 0.40625 | F4: =ROUND((Table10[[#This Row],[LandingTime]]-Table10[[#This Row],[TakeOffTime]])*1440,0) -> 25 | G4: ='2965B'!S12 -> 6 | H4: ='2965B'!P12 -> FALSE | I4: ='2965B'!$F$2 -> ZE495 | J4: ='2965B'!$O$2 -> 46275 | K4: ='2965B'!L12 -> FALSE | L4: ='2965B'!M12 -> TRUE
A5: ='2965B'!B13 -> Bramwell | B5: ='2965B'!C13 -> Ansell | C5: ='2965B'!D13 -> SCT QGI | D5: ='2965B'!E13 -> 0.40972222 | E5: ='2965B'!F13 -> 0.41041667 | F5: =ROUND((Table10[[#This Row],[LandingTime]]-Table10[[#This Row],[TakeOffTime]])*1440,0) -> 1 | G5: ='2965B'!S13 -> 1 | H5: ='2965B'!P13 -> TRUE | I5: ='2965B'!$F$2 -> ZE495 | J5: ='2965B'!$O$2 -> 46275 | K5: ='2965B'!L13 -> FALSE | L5: ='2965B'!M13 -> TRUE
A6: ='2965B'!B14 -> Ashby | B6: ='2965B'!C14 -> Bloggs | C6: ='2965B'!D14 -> PAX | D6: ='2965B'!E14 -> 0.41666667 | E6: ='2965B'!F14 -> 0.42013889 | F6: =ROUND((Table10[[#This Row],[LandingTime]]-Table10[[#This Row],[TakeOffTime]])*1440,0) -> 5 | G6: ='2965B'!S14 -> 1 | H6: ='2965B'!P14 -> FALSE | I6: ='2965B'!$F$2 -> ZE495 | J6: ='2965B'!$O$2 -> 46275 | K6: ='2965B'!L14 -> FALSE | L6: ='2965B'!M14 -> FALSE
A7: ='2965B'!B15 -> 0 | B7: ='2965B'!C15 -> 0 | C7: ='2965B'!D15 -> 0 | D7: ='2965B'!E15 -> 0 | E7: ='2965B'!F15 -> 0 | F7: =ROUND((Table10[[#This Row],[LandingTime]]-Table10[[#This Row],[TakeOffTime]])*1440,0) -> 0 | G7: ='2965B'!S15 | H7: ='2965B'!P15 -> FALSE | I7: ='2965B'!$F$2 -> ZE495 | J7: ='2965B'!$O$2 -> 46275 | K7: ='2965B'!L15 -> FALSE | L7: ='2965B'!M15 -> FALSE
A8: ='2965B'!B16 -> 0 | B8: ='2965B'!C16 -> 0 | C8: ='2965B'!D16 -> 0 | D8: ='2965B'!E16 -> 0 | E8: ='2965B'!F16 -> 0 | F8: =ROUND((Table10[[#This Row],[LandingTime]]-Table10[[#This Row],[TakeOffTime]])*1440,0) -> 0 | G8: ='2965B'!S16 | H8: ='2965B'!P16 -> FALSE | I8: ='2965B'!$F$2 -> ZE495 | J8: ='2965B'!$O$2 -> 46275 | K8: ='2965B'!L16 -> FALSE | L8: ='2965B'!M16 -> FALSE
A9: ='2965B'!B17 -> 0 | B9: ='2965B'!C17 -> 0 | C9: ='2965B'!D17 -> 0 | D9: ='2965B'!E17 -> 0 | E9: ='2965B'!F17 -> 0 | F9: =ROUND((Table10[[#This Row],[LandingTime]]-Table10[[#This Row],[TakeOffTime]])*1440,0) -> 0 | G9: ='2965B'!S17 | H9: ='2965B'!P17 -> FALSE | I9: ='2965B'!$F$2 -> ZE495 | J9: ='2965B'!$O$2 -> 46275 | K9: ='2965B'!L17 -> FALSE | L9: ='2965B'!M17 -> FALSE
A10: ='2965B'!B18 -> 0 | B10: ='2965B'!C18 -> 0 | C10: ='2965B'!D18 -> 0 | D10: ='2965B'!E18 -> 0 | E10: ='2965B'!F18 -> 0 | F10: =ROUND((Table10[[#This Row],[LandingTime]]-Table10[[#This Row],[TakeOffTime]])*1440,0) -> 0 | G10: ='2965B'!S18 | H10: ='2965B'!P18 -> FALSE | I10: ='2965B'!$F$2 -> ZE495 | J10: ='2965B'!$O$2 -> 46275 | K10: ='2965B'!L18 -> FALSE | L10: ='2965B'!M18 -> FALSE
A11: ='2965B'!B19 -> 0 | B11: ='2965B'!C19 -> 0 | C11: ='2965B'!D19 -> 0 | D11: ='2965B'!E19 -> 0 | E11: ='2965B'!F19 -> 0 | F11: =ROUND((Table10[[#This Row],[LandingTime]]-Table10[[#This Row],[TakeOffTime]])*1440,0) -> 0 | G11: ='2965B'!S19 | H11: ='2965B'!P19 -> FALSE | I11: ='2965B'!$F$2 -> ZE495 | J11: ='2965B'!$O$2 -> 46275 | K11: ='2965B'!L19 -> FALSE | L11: ='2965B'!M19 -> FALSE
A12: ='2965B'!B20 -> 0 | B12: ='2965B'!C20 -> 0 | C12: ='2965B'!D20 -> 0 | D12: ='2965B'!E20 -> 0 | E12: ='2965B'!F20 -> 0 | F12: =ROUND((Table10[[#This Row],[LandingTime]]-Table10[[#This Row],[TakeOffTime]])*1440,0) -> 0 | G12: ='2965B'!S20 | H12: ='2965B'!P20 -> FALSE | I12: ='2965B'!$F$2 -> ZE495 | J12: ='2965B'!$O$2 -> 46275 | K12: ='2965B'!L20 -> FALSE | L12: ='2965B'!M20 -> FALSE
A13: ='2965B'!B21 -> 0 | B13: ='2965B'!C21 -> 0 | C13: ='2965B'!D21 -> 0 | D13: ='2965B'!E21 -> 0 | E13: ='2965B'!F21 -> 0 | F13: =ROUND((Table10[[#This Row],[LandingTime]]-Table10[[#This Row],[TakeOffTime]])*1440,0) -> 0 | G13: ='2965B'!S21 | H13: ='2965B'!P21 -> FALSE | I13: ='2965B'!$F$2 -> ZE495 | J13: ='2965B'!$O$2 -> 46275 | K13: ='2965B'!L21 -> FALSE | L13: ='2965B'!M21 -> FALSE
... A31: ='2965B'!B39 -> 0 | B31: ='2965B'!C39 -> 0 | C31: ='2965B'!D39 -> 0 | D31: ='2965B'!E39 -> 0 | E31: ='2965B'!F39 -> 0 | F31: =ROUND((Table10[[#This Row],[LandingTime]]-Table10[[#This Row],[TakeOffTime]])*1440,0) -> 0 | G31: ='2965B'!S39 | H31: ='2965B'!P39 -> FALSE | I31: ='2965B'!$F$2 -> ZE495 | J31: ='2965B'!$O$2 -> 46275 | K31: ='2965B'!L39 -> FALSE | L31: ='2965B'!M39 -> FALSE

Sheet _AIRCRAFT
A1: Date | B1: Aircraft | C1: Hours After | D1: Launches After
A2: ='2965B'!$O$2 -> 0 | B2: ='2965B'!$F$2 -> 0 | C2: ='2965B'!$C$4+SUM('2965B'!$G$40:$N$40) -> 0 | D2: ='2965B'!$C$5+SUM('2965B'!$G$41:$N$41) -> 0
